*** Starting uWSGI 2.0.19.1 (64bit) on [Sun Aug 29 18:57:51 2021] ***
compiled with version: 7.5.0 on 29 August 2021 18:36:23
os: Linux-4.4.0-1128-aws #142-Ubuntu SMP Fri Apr 16 12:42:33 UTC 2021
nodename: goorm
machine: x86_64
clock source: unix
pcre jit disabled
detected number of CPU cores: 2
current working directory: /workspace/mbittest
writing pidfile to /workspace/mbittest/tmp/MBIT.pid
detected binary path: /workspace/mbittest/SuperHong/bin/uwsgi
*** WARNING: you are running uWSGI as root !!! (use the --uid flag) *** 
chdir() to /workspace/mbittest/
your memory page size is 4096 bytes
detected max file descriptor number: 1024
building mime-types dictionary from file /etc/mime.types...554 entry found
lock engine: pthread robust mutexes
thunder lock: disabled (you can enable it with --thunder-lock)
uWSGI http bound on :80 fd 4
uwsgi socket 0 bound to TCP address 127.0.0.1:40136 (port auto-assigned) fd 3
*** WARNING: you are running uWSGI as root !!! (use the --uid flag) *** 
Python version: 3.7.4 (default, Nov  4 2020, 10:17:35)  [GCC 7.4.0]
PEP 405 virtualenv detected: /workspace/mbittest/SuperHong/
Set PythonHome to /workspace/mbittest/SuperHong/
Python main interpreter initialized at 0x558317d986d0
*** WARNING: you are running uWSGI as root !!! (use the --uid flag) *** 
python threads support enabled
your server socket listen backlog is limited to 100 connections
your mercy for graceful operations on workers is 60 seconds
mapped 145840 bytes (142 KB) for 1 cores
*** Operational MODE: single process ***
WSGI app 0 (mountpoint='') ready in 1 seconds on interpreter 0x558317d986d0 pid: 8886 (default app)
*** WARNING: you are running uWSGI as root !!! (use the --uid flag) *** 
spawned uWSGI master process (pid: 8886)
spawned uWSGI worker 1 (pid: 8890, cores: 1)
spawned uWSGI http 1 (pid: 8891)
subprocess 8887 exited with code 0
SIGINT/SIGQUIT received...killing workers...
gateway "uWSGI http 1" has been buried (pid: 8891)
worker 1 buried after 1 seconds
goodbye to uWSGI.
VACUUM: pidfile removed.
*** Starting uWSGI 2.0.19.1 (64bit) on [Sun Aug 29 19:04:42 2021] ***
compiled with version: 7.5.0 on 29 August 2021 18:36:23
os: Linux-4.4.0-1128-aws #142-Ubuntu SMP Fri Apr 16 12:42:33 UTC 2021
nodename: goorm
machine: x86_64
clock source: unix
pcre jit disabled
detected number of CPU cores: 2
current working directory: /workspace/mbittest
writing pidfile to /workspace/mbittest/tmp/MBIT.pid
detected binary path: /workspace/mbittest/SuperHong/bin/uwsgi
chdir() to /workspace/mbittest/
your memory page size is 4096 bytes
detected max file descriptor number: 1024
building mime-types dictionary from file /etc/mime.types...554 entry found
lock engine: pthread robust mutexes
thunder lock: disabled (you can enable it with --thunder-lock)
uwsgi socket 0 bound to UNIX address /workspace/mbittest/tmp/MBIT.sock fd 3
*** WARNING: you are running uWSGI as root !!! (use the --uid flag) *** 
Python version: 3.7.4 (default, Nov  4 2020, 10:17:35)  [GCC 7.4.0]
PEP 405 virtualenv detected: /workspace/mbittest/SuperHong/
Set PythonHome to /workspace/mbittest/SuperHong/
Python main interpreter initialized at 0x55aa490d81b0
*** WARNING: you are running uWSGI as root !!! (use the --uid flag) *** 
python threads support enabled
your server socket listen backlog is limited to 100 connections
your mercy for graceful operations on workers is 60 seconds
mapped 145840 bytes (142 KB) for 1 cores
*** Operational MODE: single process ***
WSGI app 0 (mountpoint='') ready in 1 seconds on interpreter 0x55aa490d81b0 pid: 9309 (default app)
*** WARNING: you are running uWSGI as root !!! (use the --uid flag) *** 
spawned uWSGI master process (pid: 9309)
spawned uWSGI worker 1 (pid: 9313, cores: 1)
subprocess 9310 exited with code 0
[pid: 9313|app: 0|req: 1/1] 172.17.0.1 () {58 vars in 2837 bytes} [Sun Aug 29 19:04:52 2021] GET / => generated 4097 bytes in 140 msecs (HTTP/1.1 200) 5 headers in 167 bytes (1 switches on core 0)
SIGINT/SIGQUIT received...killing workers...
worker 1 buried after 1 seconds
goodbye to uWSGI.
VACUUM: pidfile removed.
VACUUM: unix socket /workspace/mbittest/tmp/MBIT.sock removed.
*** Starting uWSGI 2.0.19.1 (64bit) on [Sun Aug 29 19:10:26 2021] ***
compiled with version: 7.5.0 on 29 August 2021 18:36:23
os: Linux-4.4.0-1128-aws #142-Ubuntu SMP Fri Apr 16 12:42:33 UTC 2021
nodename: goorm
machine: x86_64
clock source: unix
pcre jit disabled
detected number of CPU cores: 2
current working directory: /workspace/mbittest
writing pidfile to /workspace/mbittest/tmp/MBIT.pid
detected binary path: /workspace/mbittest/SuperHong/bin/uwsgi
chdir() to /workspace/mbittest/
your memory page size is 4096 bytes
detected max file descriptor number: 1024
building mime-types dictionary from file /etc/mime.types...554 entry found
lock engine: pthread robust mutexes
thunder lock: disabled (you can enable it with --thunder-lock)
uwsgi socket 0 bound to UNIX address /workspace/mbittest/tmp/MBIT.sock fd 3
*** WARNING: you are running uWSGI as root !!! (use the --uid flag) *** 
Python version: 3.7.4 (default, Nov  4 2020, 10:17:35)  [GCC 7.4.0]
PEP 405 virtualenv detected: /workspace/mbittest/SuperHong/
Set PythonHome to /workspace/mbittest/SuperHong/
Python main interpreter initialized at 0x562dbe6bd220
*** WARNING: you are running uWSGI as root !!! (use the --uid flag) *** 
python threads support enabled
your server socket listen backlog is limited to 100 connections
your mercy for graceful operations on workers is 60 seconds
mapped 145840 bytes (142 KB) for 1 cores
*** Operational MODE: single process ***
WSGI app 0 (mountpoint='') ready in 1 seconds on interpreter 0x562dbe6bd220 pid: 9824 (default app)
*** WARNING: you are running uWSGI as root !!! (use the --uid flag) *** 
spawned uWSGI master process (pid: 9824)
spawned uWSGI worker 1 (pid: 9829, cores: 1)
subprocess 9825 exited with code 0
[pid: 9829|app: 0|req: 1/1] 172.17.0.1 () {58 vars in 2791 bytes} [Sun Aug 29 19:10:29 2021] GET / => generated 4097 bytes in 233 msecs (HTTP/1.1 200) 5 headers in 167 bytes (1 switches on core 0)
SIGINT/SIGQUIT received...killing workers...
worker 1 buried after 1 seconds
goodbye to uWSGI.
VACUUM: pidfile removed.
VACUUM: unix socket /workspace/mbittest/tmp/MBIT.sock removed.
*** Starting uWSGI 2.0.19.1 (64bit) on [Sun Aug 29 20:54:30 2021] ***
compiled with version: 7.5.0 on 29 August 2021 18:36:23
os: Linux-4.4.0-1128-aws #142-Ubuntu SMP Fri Apr 16 12:42:33 UTC 2021
nodename: goorm
machine: x86_64
clock source: unix
pcre jit disabled
detected number of CPU cores: 2
current working directory: /workspace/mbittest
writing pidfile to /workspace/mbittest/tmp/MBIT.pid
detected binary path: /workspace/mbittest/SuperHong/bin/uwsgi
chdir() to /workspace/mbittest/
your memory page size is 4096 bytes
detected max file descriptor number: 1024
building mime-types dictionary from file /etc/mime.types...554 entry found
lock engine: pthread robust mutexes
thunder lock: disabled (you can enable it with --thunder-lock)
uwsgi socket 0 bound to UNIX address /workspace/mbittest/tmp/MBIT.sock fd 3
*** WARNING: you are running uWSGI as root !!! (use the --uid flag) *** 
Python version: 3.7.4 (default, Nov  4 2020, 10:17:35)  [GCC 7.4.0]
PEP 405 virtualenv detected: /workspace/mbittest/SuperHong/
Set PythonHome to /workspace/mbittest/SuperHong/
Python main interpreter initialized at 0x555f89606220
*** WARNING: you are running uWSGI as root !!! (use the --uid flag) *** 
python threads support enabled
your server socket listen backlog is limited to 100 connections
your mercy for graceful operations on workers is 60 seconds
mapped 145840 bytes (142 KB) for 1 cores
*** Operational MODE: single process ***
WSGI app 0 (mountpoint='') ready in 2 seconds on interpreter 0x555f89606220 pid: 15555 (default app)
*** WARNING: you are running uWSGI as root !!! (use the --uid flag) *** 
spawned uWSGI master process (pid: 15555)
spawned uWSGI worker 1 (pid: 15561, cores: 1)
subprocess 15556 exited with code 0
[pid: 15561|app: 0|req: 1/1] 172.17.0.1 () {58 vars in 2791 bytes} [Sun Aug 29 20:54:33 2021] GET / => generated 4097 bytes in 160 msecs (HTTP/1.1 200) 5 headers in 167 bytes (1 switches on core 0)
SIGINT/SIGQUIT received...killing workers...
worker 1 buried after 1 seconds
goodbye to uWSGI.
VACUUM: pidfile removed.
VACUUM: unix socket /workspace/mbittest/tmp/MBIT.sock removed.
*** Starting uWSGI 2.0.19.1 (64bit) on [Sun Aug 29 21:06:11 2021] ***
compiled with version: 7.5.0 on 29 August 2021 18:36:23
os: Linux-4.4.0-1128-aws #142-Ubuntu SMP Fri Apr 16 12:42:33 UTC 2021
nodename: goorm
machine: x86_64
clock source: unix
pcre jit disabled
detected number of CPU cores: 2
current working directory: /workspace/mbittest
writing pidfile to /workspace/mbittest/tmp/MBIT.pid
detected binary path: /workspace/mbittest/SuperHong/bin/uwsgi
chdir() to /workspace/mbittest/
your memory page size is 4096 bytes
detected max file descriptor number: 1024
building mime-types dictionary from file /etc/mime.types...554 entry found
lock engine: pthread robust mutexes
thunder lock: disabled (you can enable it with --thunder-lock)
uwsgi socket 0 bound to UNIX address /workspace/mbittest/tmp/MBIT.sock fd 3
*** WARNING: you are running uWSGI as root !!! (use the --uid flag) *** 
Python version: 3.7.4 (default, Nov  4 2020, 10:17:35)  [GCC 7.4.0]
PEP 405 virtualenv detected: /workspace/mbittest/SuperHong/
Set PythonHome to /workspace/mbittest/SuperHong/
Python main interpreter initialized at 0x55da88d31220
*** WARNING: you are running uWSGI as root !!! (use the --uid flag) *** 
python threads support enabled
your server socket listen backlog is limited to 100 connections
your mercy for graceful operations on workers is 60 seconds
mapped 145840 bytes (142 KB) for 1 cores
*** Operational MODE: single process ***
WSGI app 0 (mountpoint='') ready in 2 seconds on interpreter 0x55da88d31220 pid: 16198 (default app)
*** WARNING: you are running uWSGI as root !!! (use the --uid flag) *** 
spawned uWSGI master process (pid: 16198)
spawned uWSGI worker 1 (pid: 16203, cores: 1)
subprocess 16199 exited with code 0
Internal Server Error: /
Traceback (most recent call last):
  File "/workspace/mbittest/SuperHong/lib/python3.7/site-packages/django/core/handlers/exception.py", line 47, in inner
    response = get_response(request)
  File "/workspace/mbittest/SuperHong/lib/python3.7/site-packages/django/core/handlers/base.py", line 167, in _get_response
    callback, callback_args, callback_kwargs = self.resolve_request(request)
  File "/workspace/mbittest/SuperHong/lib/python3.7/site-packages/django/core/handlers/base.py", line 290, in resolve_request
    resolver_match = resolver.resolve(request.path_info)
  File "/workspace/mbittest/SuperHong/lib/python3.7/site-packages/django/urls/resolvers.py", line 556, in resolve
    for pattern in self.url_patterns:
  File "/workspace/mbittest/SuperHong/lib/python3.7/site-packages/django/utils/functional.py", line 48, in __get__
    res = instance.__dict__[self.name] = self.func(instance)
  File "/workspace/mbittest/SuperHong/lib/python3.7/site-packages/django/urls/resolvers.py", line 598, in url_patterns
    patterns = getattr(self.urlconf_module, "urlpatterns", self.urlconf_module)
  File "/workspace/mbittest/SuperHong/lib/python3.7/site-packages/django/utils/functional.py", line 48, in __get__
    res = instance.__dict__[self.name] = self.func(instance)
  File "/workspace/mbittest/SuperHong/lib/python3.7/site-packages/django/urls/resolvers.py", line 591, in urlconf_module
    return import_module(self.urlconf_name)
  File "/usr/local/lib/python3.7/importlib/__init__.py", line 127, in import_module
    return _bootstrap._gcd_import(name[level:], package, level)
  File "<frozen importlib._bootstrap>", line 1006, in _gcd_import
  File "<frozen importlib._bootstrap>", line 983, in _find_and_load
  File "<frozen importlib._bootstrap>", line 967, in _find_and_load_unlocked
  File "<frozen importlib._bootstrap>", line 677, in _load_unlocked
  File "<frozen importlib._bootstrap_external>", line 728, in exec_module
  File "<frozen importlib._bootstrap>", line 219, in _call_with_frames_removed
  File "./MBIT/urls.py", line 11, in <module>
    path('result/<int:developer_id>', views.result),
AttributeError: module 'main.views' has no attribute 'result'
[pid: 16203|app: 0|req: 1/1] 172.17.0.1 () {58 vars in 2791 bytes} [Sun Aug 29 21:06:13 2021] GET / => generated 113233 bytes in 523 msecs (HTTP/1.1 500) 6 headers in 187 bytes (1 switches on core 0)
Internal Server Error: /
Traceback (most recent call last):
  File "/workspace/mbittest/SuperHong/lib/python3.7/site-packages/django/core/handlers/exception.py", line 47, in inner
    response = get_response(request)
  File "/workspace/mbittest/SuperHong/lib/python3.7/site-packages/django/core/handlers/base.py", line 167, in _get_response
    callback, callback_args, callback_kwargs = self.resolve_request(request)
  File "/workspace/mbittest/SuperHong/lib/python3.7/site-packages/django/core/handlers/base.py", line 290, in resolve_request
    resolver_match = resolver.resolve(request.path_info)
  File "/workspace/mbittest/SuperHong/lib/python3.7/site-packages/django/urls/resolvers.py", line 556, in resolve
    for pattern in self.url_patterns:
  File "/workspace/mbittest/SuperHong/lib/python3.7/site-packages/django/utils/functional.py", line 48, in __get__
    res = instance.__dict__[self.name] = self.func(instance)
  File "/workspace/mbittest/SuperHong/lib/python3.7/site-packages/django/urls/resolvers.py", line 598, in url_patterns
    patterns = getattr(self.urlconf_module, "urlpatterns", self.urlconf_module)
  File "/workspace/mbittest/SuperHong/lib/python3.7/site-packages/django/utils/functional.py", line 48, in __get__
    res = instance.__dict__[self.name] = self.func(instance)
  File "/workspace/mbittest/SuperHong/lib/python3.7/site-packages/django/urls/resolvers.py", line 591, in urlconf_module
    return import_module(self.urlconf_name)
  File "/usr/local/lib/python3.7/importlib/__init__.py", line 127, in import_module
    return _bootstrap._gcd_import(name[level:], package, level)
  File "<frozen importlib._bootstrap>", line 1006, in _gcd_import
  File "<frozen importlib._bootstrap>", line 983, in _find_and_load
  File "<frozen importlib._bootstrap>", line 967, in _find_and_load_unlocked
  File "<frozen importlib._bootstrap>", line 677, in _load_unlocked
  File "<frozen importlib._bootstrap_external>", line 728, in exec_module
  File "<frozen importlib._bootstrap>", line 219, in _call_with_frames_removed
  File "./MBIT/urls.py", line 11, in <module>
    path('result/<int:developer_id>', views.result),
AttributeError: module 'main.views' has no attribute 'result'
[pid: 16203|app: 0|req: 2/2] 172.17.0.1 () {58 vars in 2791 bytes} [Sun Aug 29 21:06:44 2021] GET / => generated 113233 bytes in 173 msecs (HTTP/1.1 500) 6 headers in 187 bytes (1 switches on core 0)
SIGINT/SIGQUIT received...killing workers...
worker 1 buried after 1 seconds
goodbye to uWSGI.
VACUUM: pidfile removed.
VACUUM: unix socket /workspace/mbittest/tmp/MBIT.sock removed.
*** Starting uWSGI 2.0.19.1 (64bit) on [Sun Aug 29 21:12:11 2021] ***
compiled with version: 7.5.0 on 29 August 2021 18:36:23
os: Linux-4.4.0-1128-aws #142-Ubuntu SMP Fri Apr 16 12:42:33 UTC 2021
nodename: goorm
machine: x86_64
clock source: unix
pcre jit disabled
detected number of CPU cores: 2
current working directory: /workspace/mbittest
writing pidfile to /workspace/mbittest/tmp/MBIT.pid
detected binary path: /workspace/mbittest/SuperHong/bin/uwsgi
chdir() to /workspace/mbittest/
your memory page size is 4096 bytes
detected max file descriptor number: 1024
building mime-types dictionary from file /etc/mime.types...554 entry found
lock engine: pthread robust mutexes
thunder lock: disabled (you can enable it with --thunder-lock)
uwsgi socket 0 bound to UNIX address /workspace/mbittest/tmp/MBIT.sock fd 3
*** WARNING: you are running uWSGI as root !!! (use the --uid flag) *** 
Python version: 3.7.4 (default, Nov  4 2020, 10:17:35)  [GCC 7.4.0]
PEP 405 virtualenv detected: /workspace/mbittest/SuperHong/
Set PythonHome to /workspace/mbittest/SuperHong/
Python main interpreter initialized at 0x55818d26d220
*** WARNING: you are running uWSGI as root !!! (use the --uid flag) *** 
python threads support enabled
your server socket listen backlog is limited to 100 connections
your mercy for graceful operations on workers is 60 seconds
mapped 145840 bytes (142 KB) for 1 cores
*** Operational MODE: single process ***
WSGI app 0 (mountpoint='') ready in 2 seconds on interpreter 0x55818d26d220 pid: 16524 (default app)
*** WARNING: you are running uWSGI as root !!! (use the --uid flag) *** 
spawned uWSGI master process (pid: 16524)
spawned uWSGI worker 1 (pid: 16529, cores: 1)
subprocess 16525 exited with code 0
Internal Server Error: /
Traceback (most recent call last):
  File "/workspace/mbittest/SuperHong/lib/python3.7/site-packages/django/core/handlers/exception.py", line 47, in inner
    response = get_response(request)
  File "/workspace/mbittest/SuperHong/lib/python3.7/site-packages/django/core/handlers/base.py", line 167, in _get_response
    callback, callback_args, callback_kwargs = self.resolve_request(request)
  File "/workspace/mbittest/SuperHong/lib/python3.7/site-packages/django/core/handlers/base.py", line 290, in resolve_request
    resolver_match = resolver.resolve(request.path_info)
  File "/workspace/mbittest/SuperHong/lib/python3.7/site-packages/django/urls/resolvers.py", line 556, in resolve
    for pattern in self.url_patterns:
  File "/workspace/mbittest/SuperHong/lib/python3.7/site-packages/django/utils/functional.py", line 48, in __get__
    res = instance.__dict__[self.name] = self.func(instance)
  File "/workspace/mbittest/SuperHong/lib/python3.7/site-packages/django/urls/resolvers.py", line 598, in url_patterns
    patterns = getattr(self.urlconf_module, "urlpatterns", self.urlconf_module)
  File "/workspace/mbittest/SuperHong/lib/python3.7/site-packages/django/utils/functional.py", line 48, in __get__
    res = instance.__dict__[self.name] = self.func(instance)
  File "/workspace/mbittest/SuperHong/lib/python3.7/site-packages/django/urls/resolvers.py", line 591, in urlconf_module
    return import_module(self.urlconf_name)
  File "/usr/local/lib/python3.7/importlib/__init__.py", line 127, in import_module
    return _bootstrap._gcd_import(name[level:], package, level)
  File "<frozen importlib._bootstrap>", line 1006, in _gcd_import
  File "<frozen importlib._bootstrap>", line 983, in _find_and_load
  File "<frozen importlib._bootstrap>", line 967, in _find_and_load_unlocked
  File "<frozen importlib._bootstrap>", line 677, in _load_unlocked
  File "<frozen importlib._bootstrap_external>", line 728, in exec_module
  File "<frozen importlib._bootstrap>", line 219, in _call_with_frames_removed
  File "./MBIT/urls.py", line 11, in <module>
    path('result/<int:developer_id>', views.result),
AttributeError: module 'main.views' has no attribute 'result'
[pid: 16529|app: 0|req: 1/1] 172.17.0.1 () {58 vars in 2791 bytes} [Sun Aug 29 21:12:13 2021] GET / => generated 113233 bytes in 621 msecs (HTTP/1.1 500) 6 headers in 187 bytes (1 switches on core 0)
SIGINT/SIGQUIT received...killing workers...
worker 1 buried after 1 seconds
goodbye to uWSGI.
VACUUM: pidfile removed.
VACUUM: unix socket /workspace/mbittest/tmp/MBIT.sock removed.
*** Starting uWSGI 2.0.19.1 (64bit) on [Sun Aug 29 21:12:53 2021] ***
compiled with version: 7.5.0 on 29 August 2021 18:36:23
os: Linux-4.4.0-1128-aws #142-Ubuntu SMP Fri Apr 16 12:42:33 UTC 2021
nodename: goorm
machine: x86_64
clock source: unix
pcre jit disabled
detected number of CPU cores: 2
current working directory: /workspace/mbittest
writing pidfile to /workspace/mbittest/tmp/MBIT.pid
detected binary path: /workspace/mbittest/SuperHong/bin/uwsgi
chdir() to /workspace/mbittest/
your memory page size is 4096 bytes
detected max file descriptor number: 1024
building mime-types dictionary from file /etc/mime.types...554 entry found
lock engine: pthread robust mutexes
thunder lock: disabled (you can enable it with --thunder-lock)
uwsgi socket 0 bound to UNIX address /workspace/mbittest/tmp/MBIT.sock fd 3
*** WARNING: you are running uWSGI as root !!! (use the --uid flag) *** 
Python version: 3.7.4 (default, Nov  4 2020, 10:17:35)  [GCC 7.4.0]
PEP 405 virtualenv detected: /workspace/mbittest/SuperHong/
Set PythonHome to /workspace/mbittest/SuperHong/
Python main interpreter initialized at 0x56386a23b220
*** WARNING: you are running uWSGI as root !!! (use the --uid flag) *** 
python threads support enabled
your server socket listen backlog is limited to 100 connections
your mercy for graceful operations on workers is 60 seconds
mapped 145840 bytes (142 KB) for 1 cores
*** Operational MODE: single process ***
WSGI app 0 (mountpoint='') ready in 1 seconds on interpreter 0x56386a23b220 pid: 16580 (default app)
*** WARNING: you are running uWSGI as root !!! (use the --uid flag) *** 
spawned uWSGI master process (pid: 16580)
spawned uWSGI worker 1 (pid: 16585, cores: 1)
subprocess 16581 exited with code 0
Internal Server Error: /
Traceback (most recent call last):
  File "/workspace/mbittest/SuperHong/lib/python3.7/site-packages/django/core/handlers/exception.py", line 47, in inner
    response = get_response(request)
  File "/workspace/mbittest/SuperHong/lib/python3.7/site-packages/django/core/handlers/base.py", line 167, in _get_response
    callback, callback_args, callback_kwargs = self.resolve_request(request)
  File "/workspace/mbittest/SuperHong/lib/python3.7/site-packages/django/core/handlers/base.py", line 290, in resolve_request
    resolver_match = resolver.resolve(request.path_info)
  File "/workspace/mbittest/SuperHong/lib/python3.7/site-packages/django/urls/resolvers.py", line 556, in resolve
    for pattern in self.url_patterns:
  File "/workspace/mbittest/SuperHong/lib/python3.7/site-packages/django/utils/functional.py", line 48, in __get__
    res = instance.__dict__[self.name] = self.func(instance)
  File "/workspace/mbittest/SuperHong/lib/python3.7/site-packages/django/urls/resolvers.py", line 598, in url_patterns
    patterns = getattr(self.urlconf_module, "urlpatterns", self.urlconf_module)
  File "/workspace/mbittest/SuperHong/lib/python3.7/site-packages/django/utils/functional.py", line 48, in __get__
    res = instance.__dict__[self.name] = self.func(instance)
  File "/workspace/mbittest/SuperHong/lib/python3.7/site-packages/django/urls/resolvers.py", line 591, in urlconf_module
    return import_module(self.urlconf_name)
  File "/usr/local/lib/python3.7/importlib/__init__.py", line 127, in import_module
    return _bootstrap._gcd_import(name[level:], package, level)
  File "<frozen importlib._bootstrap>", line 1006, in _gcd_import
  File "<frozen importlib._bootstrap>", line 983, in _find_and_load
  File "<frozen importlib._bootstrap>", line 967, in _find_and_load_unlocked
  File "<frozen importlib._bootstrap>", line 677, in _load_unlocked
  File "<frozen importlib._bootstrap_external>", line 728, in exec_module
  File "<frozen importlib._bootstrap>", line 219, in _call_with_frames_removed
  File "./MBIT/urls.py", line 11, in <module>
    path('result/<int:developer_id>', views.result),
AttributeError: module 'main.views' has no attribute 'result'
[pid: 16585|app: 0|req: 1/1] 172.17.0.1 () {58 vars in 2791 bytes} [Sun Aug 29 21:12:58 2021] GET / => generated 113233 bytes in 507 msecs (HTTP/1.1 500) 6 headers in 187 bytes (1 switches on core 0)
Internal Server Error: /
Traceback (most recent call last):
  File "/workspace/mbittest/SuperHong/lib/python3.7/site-packages/django/core/handlers/exception.py", line 47, in inner
    response = get_response(request)
  File "/workspace/mbittest/SuperHong/lib/python3.7/site-packages/django/core/handlers/base.py", line 167, in _get_response
    callback, callback_args, callback_kwargs = self.resolve_request(request)
  File "/workspace/mbittest/SuperHong/lib/python3.7/site-packages/django/core/handlers/base.py", line 290, in resolve_request
    resolver_match = resolver.resolve(request.path_info)
  File "/workspace/mbittest/SuperHong/lib/python3.7/site-packages/django/urls/resolvers.py", line 556, in resolve
    for pattern in self.url_patterns:
  File "/workspace/mbittest/SuperHong/lib/python3.7/site-packages/django/utils/functional.py", line 48, in __get__
    res = instance.__dict__[self.name] = self.func(instance)
  File "/workspace/mbittest/SuperHong/lib/python3.7/site-packages/django/urls/resolvers.py", line 598, in url_patterns
    patterns = getattr(self.urlconf_module, "urlpatterns", self.urlconf_module)
  File "/workspace/mbittest/SuperHong/lib/python3.7/site-packages/django/utils/functional.py", line 48, in __get__
    res = instance.__dict__[self.name] = self.func(instance)
  File "/workspace/mbittest/SuperHong/lib/python3.7/site-packages/django/urls/resolvers.py", line 591, in urlconf_module
    return import_module(self.urlconf_name)
  File "/usr/local/lib/python3.7/importlib/__init__.py", line 127, in import_module
    return _bootstrap._gcd_import(name[level:], package, level)
  File "<frozen importlib._bootstrap>", line 1006, in _gcd_import
  File "<frozen importlib._bootstrap>", line 983, in _find_and_load
  File "<frozen importlib._bootstrap>", line 967, in _find_and_load_unlocked
  File "<frozen importlib._bootstrap>", line 677, in _load_unlocked
  File "<frozen importlib._bootstrap_external>", line 728, in exec_module
  File "<frozen importlib._bootstrap>", line 219, in _call_with_frames_removed
  File "./MBIT/urls.py", line 11, in <module>
    path('result/<int:developer_id>', views.result),
AttributeError: module 'main.views' has no attribute 'result'
[pid: 16585|app: 0|req: 2/2] 172.17.0.1 () {58 vars in 2791 bytes} [Sun Aug 29 21:13:20 2021] GET / => generated 113233 bytes in 283 msecs (HTTP/1.1 500) 6 headers in 187 bytes (1 switches on core 0)
Internal Server Error: /
Traceback (most recent call last):
  File "/workspace/mbittest/SuperHong/lib/python3.7/site-packages/django/core/handlers/exception.py", line 47, in inner
    response = get_response(request)
  File "/workspace/mbittest/SuperHong/lib/python3.7/site-packages/django/core/handlers/base.py", line 167, in _get_response
    callback, callback_args, callback_kwargs = self.resolve_request(request)
  File "/workspace/mbittest/SuperHong/lib/python3.7/site-packages/django/core/handlers/base.py", line 290, in resolve_request
    resolver_match = resolver.resolve(request.path_info)
  File "/workspace/mbittest/SuperHong/lib/python3.7/site-packages/django/urls/resolvers.py", line 556, in resolve
    for pattern in self.url_patterns:
  File "/workspace/mbittest/SuperHong/lib/python3.7/site-packages/django/utils/functional.py", line 48, in __get__
    res = instance.__dict__[self.name] = self.func(instance)
  File "/workspace/mbittest/SuperHong/lib/python3.7/site-packages/django/urls/resolvers.py", line 598, in url_patterns
    patterns = getattr(self.urlconf_module, "urlpatterns", self.urlconf_module)
  File "/workspace/mbittest/SuperHong/lib/python3.7/site-packages/django/utils/functional.py", line 48, in __get__
    res = instance.__dict__[self.name] = self.func(instance)
  File "/workspace/mbittest/SuperHong/lib/python3.7/site-packages/django/urls/resolvers.py", line 591, in urlconf_module
    return import_module(self.urlconf_name)
  File "/usr/local/lib/python3.7/importlib/__init__.py", line 127, in import_module
    return _bootstrap._gcd_import(name[level:], package, level)
  File "<frozen importlib._bootstrap>", line 1006, in _gcd_import
  File "<frozen importlib._bootstrap>", line 983, in _find_and_load
  File "<frozen importlib._bootstrap>", line 967, in _find_and_load_unlocked
  File "<frozen importlib._bootstrap>", line 677, in _load_unlocked
  File "<frozen importlib._bootstrap_external>", line 728, in exec_module
  File "<frozen importlib._bootstrap>", line 219, in _call_with_frames_removed
  File "./MBIT/urls.py", line 11, in <module>
    path('result/<int:developer_id>', views.result),
AttributeError: module 'main.views' has no attribute 'result'
[pid: 16585|app: 0|req: 3/3] 172.17.0.1 () {58 vars in 2791 bytes} [Sun Aug 29 21:14:35 2021] GET / => generated 113233 bytes in 263 msecs (HTTP/1.1 500) 6 headers in 187 bytes (1 switches on core 0)
Internal Server Error: /
Traceback (most recent call last):
  File "/workspace/mbittest/SuperHong/lib/python3.7/site-packages/django/core/handlers/exception.py", line 47, in inner
    response = get_response(request)
  File "/workspace/mbittest/SuperHong/lib/python3.7/site-packages/django/core/handlers/base.py", line 167, in _get_response
    callback, callback_args, callback_kwargs = self.resolve_request(request)
  File "/workspace/mbittest/SuperHong/lib/python3.7/site-packages/django/core/handlers/base.py", line 290, in resolve_request
    resolver_match = resolver.resolve(request.path_info)
  File "/workspace/mbittest/SuperHong/lib/python3.7/site-packages/django/urls/resolvers.py", line 556, in resolve
    for pattern in self.url_patterns:
  File "/workspace/mbittest/SuperHong/lib/python3.7/site-packages/django/utils/functional.py", line 48, in __get__
    res = instance.__dict__[self.name] = self.func(instance)
  File "/workspace/mbittest/SuperHong/lib/python3.7/site-packages/django/urls/resolvers.py", line 598, in url_patterns
    patterns = getattr(self.urlconf_module, "urlpatterns", self.urlconf_module)
  File "/workspace/mbittest/SuperHong/lib/python3.7/site-packages/django/utils/functional.py", line 48, in __get__
    res = instance.__dict__[self.name] = self.func(instance)
  File "/workspace/mbittest/SuperHong/lib/python3.7/site-packages/django/urls/resolvers.py", line 591, in urlconf_module
    return import_module(self.urlconf_name)
  File "/usr/local/lib/python3.7/importlib/__init__.py", line 127, in import_module
    return _bootstrap._gcd_import(name[level:], package, level)
  File "<frozen importlib._bootstrap>", line 1006, in _gcd_import
  File "<frozen importlib._bootstrap>", line 983, in _find_and_load
  File "<frozen importlib._bootstrap>", line 967, in _find_and_load_unlocked
  File "<frozen importlib._bootstrap>", line 677, in _load_unlocked
  File "<frozen importlib._bootstrap_external>", line 728, in exec_module
  File "<frozen importlib._bootstrap>", line 219, in _call_with_frames_removed
  File "./MBIT/urls.py", line 11, in <module>
    path('result/<int:developer_id>/', views.result),
AttributeError: module 'main.views' has no attribute 'result'
[pid: 16585|app: 0|req: 4/4] 172.17.0.1 () {58 vars in 2792 bytes} [Sun Aug 29 21:16:33 2021] GET / => generated 113236 bytes in 421 msecs (HTTP/1.1 500) 6 headers in 187 bytes (1 switches on core 0)
Internal Server Error: /
Traceback (most recent call last):
  File "/workspace/mbittest/SuperHong/lib/python3.7/site-packages/django/core/handlers/exception.py", line 47, in inner
    response = get_response(request)
  File "/workspace/mbittest/SuperHong/lib/python3.7/site-packages/django/core/handlers/base.py", line 167, in _get_response
    callback, callback_args, callback_kwargs = self.resolve_request(request)
  File "/workspace/mbittest/SuperHong/lib/python3.7/site-packages/django/core/handlers/base.py", line 290, in resolve_request
    resolver_match = resolver.resolve(request.path_info)
  File "/workspace/mbittest/SuperHong/lib/python3.7/site-packages/django/urls/resolvers.py", line 556, in resolve
    for pattern in self.url_patterns:
  File "/workspace/mbittest/SuperHong/lib/python3.7/site-packages/django/utils/functional.py", line 48, in __get__
    res = instance.__dict__[self.name] = self.func(instance)
  File "/workspace/mbittest/SuperHong/lib/python3.7/site-packages/django/urls/resolvers.py", line 598, in url_patterns
    patterns = getattr(self.urlconf_module, "urlpatterns", self.urlconf_module)
  File "/workspace/mbittest/SuperHong/lib/python3.7/site-packages/django/utils/functional.py", line 48, in __get__
    res = instance.__dict__[self.name] = self.func(instance)
  File "/workspace/mbittest/SuperHong/lib/python3.7/site-packages/django/urls/resolvers.py", line 591, in urlconf_module
    return import_module(self.urlconf_name)
  File "/usr/local/lib/python3.7/importlib/__init__.py", line 127, in import_module
    return _bootstrap._gcd_import(name[level:], package, level)
  File "<frozen importlib._bootstrap>", line 1006, in _gcd_import
  File "<frozen importlib._bootstrap>", line 983, in _find_and_load
  File "<frozen importlib._bootstrap>", line 967, in _find_and_load_unlocked
  File "<frozen importlib._bootstrap>", line 677, in _load_unlocked
  File "<frozen importlib._bootstrap_external>", line 728, in exec_module
  File "<frozen importlib._bootstrap>", line 219, in _call_with_frames_removed
  File "./MBIT/urls.py", line 11, in <module>
    path('result/<int:developer_id>/', views.result),
AttributeError: module 'main.views' has no attribute 'result'
[pid: 16585|app: 0|req: 5/5] 172.17.0.1 () {58 vars in 2792 bytes} [Sun Aug 29 21:17:09 2021] GET / => generated 113236 bytes in 345 msecs (HTTP/1.1 500) 6 headers in 187 bytes (1 switches on core 0)
Internal Server Error: /
Traceback (most recent call last):
  File "/workspace/mbittest/SuperHong/lib/python3.7/site-packages/django/core/handlers/exception.py", line 47, in inner
    response = get_response(request)
  File "/workspace/mbittest/SuperHong/lib/python3.7/site-packages/django/core/handlers/base.py", line 167, in _get_response
    callback, callback_args, callback_kwargs = self.resolve_request(request)
  File "/workspace/mbittest/SuperHong/lib/python3.7/site-packages/django/core/handlers/base.py", line 290, in resolve_request
    resolver_match = resolver.resolve(request.path_info)
  File "/workspace/mbittest/SuperHong/lib/python3.7/site-packages/django/urls/resolvers.py", line 556, in resolve
    for pattern in self.url_patterns:
  File "/workspace/mbittest/SuperHong/lib/python3.7/site-packages/django/utils/functional.py", line 48, in __get__
    res = instance.__dict__[self.name] = self.func(instance)
  File "/workspace/mbittest/SuperHong/lib/python3.7/site-packages/django/urls/resolvers.py", line 598, in url_patterns
    patterns = getattr(self.urlconf_module, "urlpatterns", self.urlconf_module)
  File "/workspace/mbittest/SuperHong/lib/python3.7/site-packages/django/utils/functional.py", line 48, in __get__
    res = instance.__dict__[self.name] = self.func(instance)
  File "/workspace/mbittest/SuperHong/lib/python3.7/site-packages/django/urls/resolvers.py", line 591, in urlconf_module
    return import_module(self.urlconf_name)
  File "/usr/local/lib/python3.7/importlib/__init__.py", line 127, in import_module
    return _bootstrap._gcd_import(name[level:], package, level)
  File "<frozen importlib._bootstrap>", line 1006, in _gcd_import
  File "<frozen importlib._bootstrap>", line 983, in _find_and_load
  File "<frozen importlib._bootstrap>", line 967, in _find_and_load_unlocked
  File "<frozen importlib._bootstrap>", line 677, in _load_unlocked
  File "<frozen importlib._bootstrap_external>", line 728, in exec_module
  File "<frozen importlib._bootstrap>", line 219, in _call_with_frames_removed
  File "./MBIT/urls.py", line 11, in <module>
    path('result/<int:developer_id>/', views.result),
AttributeError: module 'main.views' has no attribute 'result'
[pid: 16585|app: 0|req: 6/6] 172.17.0.1 () {58 vars in 2792 bytes} [Sun Aug 29 21:22:04 2021] GET / => generated 113236 bytes in 337 msecs (HTTP/1.1 500) 6 headers in 187 bytes (1 switches on core 0)
Internal Server Error: /
Traceback (most recent call last):
  File "/workspace/mbittest/SuperHong/lib/python3.7/site-packages/django/core/handlers/exception.py", line 47, in inner
    response = get_response(request)
  File "/workspace/mbittest/SuperHong/lib/python3.7/site-packages/django/core/handlers/base.py", line 167, in _get_response
    callback, callback_args, callback_kwargs = self.resolve_request(request)
  File "/workspace/mbittest/SuperHong/lib/python3.7/site-packages/django/core/handlers/base.py", line 290, in resolve_request
    resolver_match = resolver.resolve(request.path_info)
  File "/workspace/mbittest/SuperHong/lib/python3.7/site-packages/django/urls/resolvers.py", line 556, in resolve
    for pattern in self.url_patterns:
  File "/workspace/mbittest/SuperHong/lib/python3.7/site-packages/django/utils/functional.py", line 48, in __get__
    res = instance.__dict__[self.name] = self.func(instance)
  File "/workspace/mbittest/SuperHong/lib/python3.7/site-packages/django/urls/resolvers.py", line 598, in url_patterns
    patterns = getattr(self.urlconf_module, "urlpatterns", self.urlconf_module)
  File "/workspace/mbittest/SuperHong/lib/python3.7/site-packages/django/utils/functional.py", line 48, in __get__
    res = instance.__dict__[self.name] = self.func(instance)
  File "/workspace/mbittest/SuperHong/lib/python3.7/site-packages/django/urls/resolvers.py", line 591, in urlconf_module
    return import_module(self.urlconf_name)
  File "/usr/local/lib/python3.7/importlib/__init__.py", line 127, in import_module
    return _bootstrap._gcd_import(name[level:], package, level)
  File "<frozen importlib._bootstrap>", line 1006, in _gcd_import
  File "<frozen importlib._bootstrap>", line 983, in _find_and_load
  File "<frozen importlib._bootstrap>", line 967, in _find_and_load_unlocked
  File "<frozen importlib._bootstrap>", line 677, in _load_unlocked
  File "<frozen importlib._bootstrap_external>", line 728, in exec_module
  File "<frozen importlib._bootstrap>", line 219, in _call_with_frames_removed
  File "./MBIT/urls.py", line 11, in <module>
    path('result/<int:developer_id>/', views.result),
AttributeError: module 'main.views' has no attribute 'result'
[pid: 16585|app: 0|req: 7/7] 172.17.0.1 () {60 vars in 2823 bytes} [Sun Aug 29 21:22:08 2021] GET / => generated 113373 bytes in 451 msecs (HTTP/1.1 500) 6 headers in 187 bytes (1 switches on core 0)
Internal Server Error: /
Traceback (most recent call last):
  File "/workspace/mbittest/SuperHong/lib/python3.7/site-packages/django/core/handlers/exception.py", line 47, in inner
    response = get_response(request)
  File "/workspace/mbittest/SuperHong/lib/python3.7/site-packages/django/core/handlers/base.py", line 167, in _get_response
    callback, callback_args, callback_kwargs = self.resolve_request(request)
  File "/workspace/mbittest/SuperHong/lib/python3.7/site-packages/django/core/handlers/base.py", line 290, in resolve_request
    resolver_match = resolver.resolve(request.path_info)
  File "/workspace/mbittest/SuperHong/lib/python3.7/site-packages/django/urls/resolvers.py", line 556, in resolve
    for pattern in self.url_patterns:
  File "/workspace/mbittest/SuperHong/lib/python3.7/site-packages/django/utils/functional.py", line 48, in __get__
    res = instance.__dict__[self.name] = self.func(instance)
  File "/workspace/mbittest/SuperHong/lib/python3.7/site-packages/django/urls/resolvers.py", line 598, in url_patterns
    patterns = getattr(self.urlconf_module, "urlpatterns", self.urlconf_module)
  File "/workspace/mbittest/SuperHong/lib/python3.7/site-packages/django/utils/functional.py", line 48, in __get__
    res = instance.__dict__[self.name] = self.func(instance)
  File "/workspace/mbittest/SuperHong/lib/python3.7/site-packages/django/urls/resolvers.py", line 591, in urlconf_module
    return import_module(self.urlconf_name)
  File "/usr/local/lib/python3.7/importlib/__init__.py", line 127, in import_module
    return _bootstrap._gcd_import(name[level:], package, level)
  File "<frozen importlib._bootstrap>", line 1006, in _gcd_import
  File "<frozen importlib._bootstrap>", line 983, in _find_and_load
  File "<frozen importlib._bootstrap>", line 967, in _find_and_load_unlocked
  File "<frozen importlib._bootstrap>", line 677, in _load_unlocked
  File "<frozen importlib._bootstrap_external>", line 728, in exec_module
  File "<frozen importlib._bootstrap>", line 219, in _call_with_frames_removed
  File "./MBIT/urls.py", line 11, in <module>
    path('result/<int:developer_id>/', views.result),
AttributeError: module 'main.views' has no attribute 'result'
[pid: 16585|app: 0|req: 8/8] 172.17.0.1 () {58 vars in 2792 bytes} [Sun Aug 29 21:22:10 2021] GET / => generated 113236 bytes in 335 msecs (HTTP/1.1 500) 6 headers in 187 bytes (1 switches on core 0)
Internal Server Error: /
Traceback (most recent call last):
  File "/workspace/mbittest/SuperHong/lib/python3.7/site-packages/django/core/handlers/exception.py", line 47, in inner
    response = get_response(request)
  File "/workspace/mbittest/SuperHong/lib/python3.7/site-packages/django/core/handlers/base.py", line 167, in _get_response
    callback, callback_args, callback_kwargs = self.resolve_request(request)
  File "/workspace/mbittest/SuperHong/lib/python3.7/site-packages/django/core/handlers/base.py", line 290, in resolve_request
    resolver_match = resolver.resolve(request.path_info)
  File "/workspace/mbittest/SuperHong/lib/python3.7/site-packages/django/urls/resolvers.py", line 556, in resolve
    for pattern in self.url_patterns:
  File "/workspace/mbittest/SuperHong/lib/python3.7/site-packages/django/utils/functional.py", line 48, in __get__
    res = instance.__dict__[self.name] = self.func(instance)
  File "/workspace/mbittest/SuperHong/lib/python3.7/site-packages/django/urls/resolvers.py", line 598, in url_patterns
    patterns = getattr(self.urlconf_module, "urlpatterns", self.urlconf_module)
  File "/workspace/mbittest/SuperHong/lib/python3.7/site-packages/django/utils/functional.py", line 48, in __get__
    res = instance.__dict__[self.name] = self.func(instance)
  File "/workspace/mbittest/SuperHong/lib/python3.7/site-packages/django/urls/resolvers.py", line 591, in urlconf_module
    return import_module(self.urlconf_name)
  File "/usr/local/lib/python3.7/importlib/__init__.py", line 127, in import_module
    return _bootstrap._gcd_import(name[level:], package, level)
  File "<frozen importlib._bootstrap>", line 1006, in _gcd_import
  File "<frozen importlib._bootstrap>", line 983, in _find_and_load
  File "<frozen importlib._bootstrap>", line 967, in _find_and_load_unlocked
  File "<frozen importlib._bootstrap>", line 677, in _load_unlocked
  File "<frozen importlib._bootstrap_external>", line 728, in exec_module
  File "<frozen importlib._bootstrap>", line 219, in _call_with_frames_removed
  File "./MBIT/urls.py", line 11, in <module>
    path('result/<int:developer_id>/', views.result),
AttributeError: module 'main.views' has no attribute 'result'
[pid: 16585|app: 0|req: 9/9] 172.17.0.1 () {58 vars in 2792 bytes} [Sun Aug 29 21:22:21 2021] GET / => generated 113236 bytes in 384 msecs (HTTP/1.1 500) 6 headers in 187 bytes (1 switches on core 0)
Internal Server Error: /
Traceback (most recent call last):
  File "/workspace/mbittest/SuperHong/lib/python3.7/site-packages/django/core/handlers/exception.py", line 47, in inner
    response = get_response(request)
  File "/workspace/mbittest/SuperHong/lib/python3.7/site-packages/django/core/handlers/base.py", line 167, in _get_response
    callback, callback_args, callback_kwargs = self.resolve_request(request)
  File "/workspace/mbittest/SuperHong/lib/python3.7/site-packages/django/core/handlers/base.py", line 290, in resolve_request
    resolver_match = resolver.resolve(request.path_info)
  File "/workspace/mbittest/SuperHong/lib/python3.7/site-packages/django/urls/resolvers.py", line 556, in resolve
    for pattern in self.url_patterns:
  File "/workspace/mbittest/SuperHong/lib/python3.7/site-packages/django/utils/functional.py", line 48, in __get__
    res = instance.__dict__[self.name] = self.func(instance)
  File "/workspace/mbittest/SuperHong/lib/python3.7/site-packages/django/urls/resolvers.py", line 598, in url_patterns
    patterns = getattr(self.urlconf_module, "urlpatterns", self.urlconf_module)
  File "/workspace/mbittest/SuperHong/lib/python3.7/site-packages/django/utils/functional.py", line 48, in __get__
    res = instance.__dict__[self.name] = self.func(instance)
  File "/workspace/mbittest/SuperHong/lib/python3.7/site-packages/django/urls/resolvers.py", line 591, in urlconf_module
    return import_module(self.urlconf_name)
  File "/usr/local/lib/python3.7/importlib/__init__.py", line 127, in import_module
    return _bootstrap._gcd_import(name[level:], package, level)
  File "<frozen importlib._bootstrap>", line 1006, in _gcd_import
  File "<frozen importlib._bootstrap>", line 983, in _find_and_load
  File "<frozen importlib._bootstrap>", line 967, in _find_and_load_unlocked
  File "<frozen importlib._bootstrap>", line 677, in _load_unlocked
  File "<frozen importlib._bootstrap_external>", line 728, in exec_module
  File "<frozen importlib._bootstrap>", line 219, in _call_with_frames_removed
  File "./MBIT/urls.py", line 11, in <module>
    path('result/<int:developer_id>', views.result, name='result'),
AttributeError: module 'main.views' has no attribute 'result'
[pid: 16585|app: 0|req: 10/10] 172.17.0.1 () {58 vars in 2791 bytes} [Sun Aug 29 21:23:31 2021] GET / => generated 113283 bytes in 545 msecs (HTTP/1.1 500) 6 headers in 187 bytes (1 switches on core 0)
SIGINT/SIGQUIT received...killing workers...
worker 1 buried after 1 seconds
goodbye to uWSGI.
VACUUM: pidfile removed.
VACUUM: unix socket /workspace/mbittest/tmp/MBIT.sock removed.
*** Starting uWSGI 2.0.19.1 (64bit) on [Sun Aug 29 21:28:23 2021] ***
compiled with version: 7.5.0 on 29 August 2021 18:36:23
os: Linux-4.4.0-1128-aws #142-Ubuntu SMP Fri Apr 16 12:42:33 UTC 2021
nodename: goorm
machine: x86_64
clock source: unix
pcre jit disabled
detected number of CPU cores: 2
current working directory: /workspace/mbittest
writing pidfile to /workspace/mbittest/tmp/MBIT.pid
detected binary path: /workspace/mbittest/SuperHong/bin/uwsgi
chdir() to /workspace/mbittest/
your memory page size is 4096 bytes
detected max file descriptor number: 1024
building mime-types dictionary from file /etc/mime.types...554 entry found
lock engine: pthread robust mutexes
thunder lock: disabled (you can enable it with --thunder-lock)
uwsgi socket 0 bound to UNIX address /workspace/mbittest/tmp/MBIT.sock fd 3
*** WARNING: you are running uWSGI as root !!! (use the --uid flag) *** 
Python version: 3.7.4 (default, Nov  4 2020, 10:17:35)  [GCC 7.4.0]
PEP 405 virtualenv detected: /workspace/mbittest/SuperHong/
Set PythonHome to /workspace/mbittest/SuperHong/
Python main interpreter initialized at 0x5653bb6cb220
*** WARNING: you are running uWSGI as root !!! (use the --uid flag) *** 
python threads support enabled
your server socket listen backlog is limited to 100 connections
your mercy for graceful operations on workers is 60 seconds
mapped 145840 bytes (142 KB) for 1 cores
*** Operational MODE: single process ***
WSGI app 0 (mountpoint='') ready in 2 seconds on interpreter 0x5653bb6cb220 pid: 17388 (default app)
*** WARNING: you are running uWSGI as root !!! (use the --uid flag) *** 
spawned uWSGI master process (pid: 17388)
spawned uWSGI worker 1 (pid: 17393, cores: 1)
subprocess 17389 exited with code 0
Internal Server Error: /
Traceback (most recent call last):
  File "/workspace/mbittest/SuperHong/lib/python3.7/site-packages/django/core/handlers/exception.py", line 47, in inner
    response = get_response(request)
  File "/workspace/mbittest/SuperHong/lib/python3.7/site-packages/django/core/handlers/base.py", line 181, in _get_response
    response = wrapped_callback(request, *callback_args, **callback_kwargs)
  File "./main/views.py", line 73, in index
    return render(request, 'main/index.html', context=context)
  File "/workspace/mbittest/SuperHong/lib/python3.7/site-packages/django/shortcuts.py", line 19, in render
    content = loader.render_to_string(template_name, context, request, using=using)
  File "/workspace/mbittest/SuperHong/lib/python3.7/site-packages/django/template/loader.py", line 61, in render_to_string
    template = get_template(template_name, using=using)
  File "/workspace/mbittest/SuperHong/lib/python3.7/site-packages/django/template/loader.py", line 19, in get_template
    raise TemplateDoesNotExist(template_name, chain=chain)
django.template.exceptions.TemplateDoesNotExist: main/index.html
[pid: 17393|app: 0|req: 1/1] 172.17.0.1 () {58 vars in 2792 bytes} [Sun Aug 29 21:28:28 2021] GET / => generated 76785 bytes in 483 msecs (HTTP/1.1 500) 6 headers in 186 bytes (1 switches on core 0)
SIGINT/SIGQUIT received...killing workers...
worker 1 buried after 1 seconds
goodbye to uWSGI.
VACUUM: pidfile removed.
VACUUM: unix socket /workspace/mbittest/tmp/MBIT.sock removed.
*** Starting uWSGI 2.0.19.1 (64bit) on [Sun Aug 29 21:28:54 2021] ***
compiled with version: 7.5.0 on 29 August 2021 18:36:23
os: Linux-4.4.0-1128-aws #142-Ubuntu SMP Fri Apr 16 12:42:33 UTC 2021
nodename: goorm
machine: x86_64
clock source: unix
pcre jit disabled
detected number of CPU cores: 2
current working directory: /workspace/mbittest
writing pidfile to /workspace/mbittest/tmp/MBIT.pid
detected binary path: /workspace/mbittest/SuperHong/bin/uwsgi
chdir() to /workspace/mbittest/
your memory page size is 4096 bytes
detected max file descriptor number: 1024
building mime-types dictionary from file /etc/mime.types...554 entry found
lock engine: pthread robust mutexes
thunder lock: disabled (you can enable it with --thunder-lock)
uwsgi socket 0 bound to UNIX address /workspace/mbittest/tmp/MBIT.sock fd 3
*** WARNING: you are running uWSGI as root !!! (use the --uid flag) *** 
Python version: 3.7.4 (default, Nov  4 2020, 10:17:35)  [GCC 7.4.0]
PEP 405 virtualenv detected: /workspace/mbittest/SuperHong/
Set PythonHome to /workspace/mbittest/SuperHong/
Python main interpreter initialized at 0x55f817d9a220
*** WARNING: you are running uWSGI as root !!! (use the --uid flag) *** 
python threads support enabled
your server socket listen backlog is limited to 100 connections
your mercy for graceful operations on workers is 60 seconds
mapped 145840 bytes (142 KB) for 1 cores
*** Operational MODE: single process ***
WSGI app 0 (mountpoint='') ready in 2 seconds on interpreter 0x55f817d9a220 pid: 17430 (default app)
*** WARNING: you are running uWSGI as root !!! (use the --uid flag) *** 
spawned uWSGI master process (pid: 17430)
spawned uWSGI worker 1 (pid: 17435, cores: 1)
subprocess 17431 exited with code 0
Internal Server Error: /
Traceback (most recent call last):
  File "/workspace/mbittest/SuperHong/lib/python3.7/site-packages/django/core/handlers/exception.py", line 47, in inner
    response = get_response(request)
  File "/workspace/mbittest/SuperHong/lib/python3.7/site-packages/django/core/handlers/base.py", line 167, in _get_response
    callback, callback_args, callback_kwargs = self.resolve_request(request)
  File "/workspace/mbittest/SuperHong/lib/python3.7/site-packages/django/core/handlers/base.py", line 290, in resolve_request
    resolver_match = resolver.resolve(request.path_info)
  File "/workspace/mbittest/SuperHong/lib/python3.7/site-packages/django/urls/resolvers.py", line 556, in resolve
    for pattern in self.url_patterns:
  File "/workspace/mbittest/SuperHong/lib/python3.7/site-packages/django/utils/functional.py", line 48, in __get__
    res = instance.__dict__[self.name] = self.func(instance)
  File "/workspace/mbittest/SuperHong/lib/python3.7/site-packages/django/urls/resolvers.py", line 598, in url_patterns
    patterns = getattr(self.urlconf_module, "urlpatterns", self.urlconf_module)
  File "/workspace/mbittest/SuperHong/lib/python3.7/site-packages/django/utils/functional.py", line 48, in __get__
    res = instance.__dict__[self.name] = self.func(instance)
  File "/workspace/mbittest/SuperHong/lib/python3.7/site-packages/django/urls/resolvers.py", line 591, in urlconf_module
    return import_module(self.urlconf_name)
  File "/usr/local/lib/python3.7/importlib/__init__.py", line 127, in import_module
    return _bootstrap._gcd_import(name[level:], package, level)
  File "<frozen importlib._bootstrap>", line 1006, in _gcd_import
  File "<frozen importlib._bootstrap>", line 983, in _find_and_load
  File "<frozen importlib._bootstrap>", line 967, in _find_and_load_unlocked
  File "<frozen importlib._bootstrap>", line 677, in _load_unlocked
  File "<frozen importlib._bootstrap_external>", line 728, in exec_module
  File "<frozen importlib._bootstrap>", line 219, in _call_with_frames_removed
  File "./MBIT/urls.py", line 11, in <module>
    path('result/<int:developer_id>', views.result, name='result'),
AttributeError: module 'main.views' has no attribute 'result'
[pid: 17435|app: 0|req: 1/1] 172.17.0.1 () {58 vars in 2792 bytes} [Sun Aug 29 21:28:56 2021] GET / => generated 113284 bytes in 607 msecs (HTTP/1.1 500) 6 headers in 187 bytes (1 switches on core 0)
SIGINT/SIGQUIT received...killing workers...
worker 1 buried after 1 seconds
goodbye to uWSGI.
VACUUM: pidfile removed.
VACUUM: unix socket /workspace/mbittest/tmp/MBIT.sock removed.
*** Starting uWSGI 2.0.19.1 (64bit) on [Sun Aug 29 21:29:48 2021] ***
compiled with version: 7.5.0 on 29 August 2021 18:36:23
os: Linux-4.4.0-1128-aws #142-Ubuntu SMP Fri Apr 16 12:42:33 UTC 2021
nodename: goorm
machine: x86_64
clock source: unix
pcre jit disabled
detected number of CPU cores: 2
current working directory: /workspace/mbittest
writing pidfile to /workspace/mbittest/tmp/MBIT.pid
detected binary path: /workspace/mbittest/SuperHong/bin/uwsgi
chdir() to /workspace/mbittest/
your memory page size is 4096 bytes
detected max file descriptor number: 1024
building mime-types dictionary from file /etc/mime.types...554 entry found
lock engine: pthread robust mutexes
thunder lock: disabled (you can enable it with --thunder-lock)
uwsgi socket 0 bound to UNIX address /workspace/mbittest/tmp/MBIT.sock fd 3
*** WARNING: you are running uWSGI as root !!! (use the --uid flag) *** 
Python version: 3.7.4 (default, Nov  4 2020, 10:17:35)  [GCC 7.4.0]
PEP 405 virtualenv detected: /workspace/mbittest/SuperHong/
Set PythonHome to /workspace/mbittest/SuperHong/
Python main interpreter initialized at 0x564aedf7d220
*** WARNING: you are running uWSGI as root !!! (use the --uid flag) *** 
python threads support enabled
your server socket listen backlog is limited to 100 connections
your mercy for graceful operations on workers is 60 seconds
mapped 145840 bytes (142 KB) for 1 cores
*** Operational MODE: single process ***
WSGI app 0 (mountpoint='') ready in 2 seconds on interpreter 0x564aedf7d220 pid: 17493 (default app)
*** WARNING: you are running uWSGI as root !!! (use the --uid flag) *** 
spawned uWSGI master process (pid: 17493)
spawned uWSGI worker 1 (pid: 17497, cores: 1)
subprocess 17494 exited with code 0
Internal Server Error: /
Traceback (most recent call last):
  File "/workspace/mbittest/SuperHong/lib/python3.7/site-packages/django/core/handlers/exception.py", line 47, in inner
    response = get_response(request)
  File "/workspace/mbittest/SuperHong/lib/python3.7/site-packages/django/core/handlers/base.py", line 167, in _get_response
    callback, callback_args, callback_kwargs = self.resolve_request(request)
  File "/workspace/mbittest/SuperHong/lib/python3.7/site-packages/django/core/handlers/base.py", line 290, in resolve_request
    resolver_match = resolver.resolve(request.path_info)
  File "/workspace/mbittest/SuperHong/lib/python3.7/site-packages/django/urls/resolvers.py", line 556, in resolve
    for pattern in self.url_patterns:
  File "/workspace/mbittest/SuperHong/lib/python3.7/site-packages/django/utils/functional.py", line 48, in __get__
    res = instance.__dict__[self.name] = self.func(instance)
  File "/workspace/mbittest/SuperHong/lib/python3.7/site-packages/django/urls/resolvers.py", line 598, in url_patterns
    patterns = getattr(self.urlconf_module, "urlpatterns", self.urlconf_module)
  File "/workspace/mbittest/SuperHong/lib/python3.7/site-packages/django/utils/functional.py", line 48, in __get__
    res = instance.__dict__[self.name] = self.func(instance)
  File "/workspace/mbittest/SuperHong/lib/python3.7/site-packages/django/urls/resolvers.py", line 591, in urlconf_module
    return import_module(self.urlconf_name)
  File "/usr/local/lib/python3.7/importlib/__init__.py", line 127, in import_module
    return _bootstrap._gcd_import(name[level:], package, level)
  File "<frozen importlib._bootstrap>", line 1006, in _gcd_import
  File "<frozen importlib._bootstrap>", line 983, in _find_and_load
  File "<frozen importlib._bootstrap>", line 967, in _find_and_load_unlocked
  File "<frozen importlib._bootstrap>", line 677, in _load_unlocked
  File "<frozen importlib._bootstrap_external>", line 728, in exec_module
  File "<frozen importlib._bootstrap>", line 219, in _call_with_frames_removed
  File "./MBIT/urls.py", line 11, in <module>
    path('result/<int:developer_id>', views.result, name='result'),
AttributeError: module 'main.views' has no attribute 'result'
[pid: 17497|app: 0|req: 1/1] 172.17.0.1 () {58 vars in 2792 bytes} [Sun Aug 29 21:29:51 2021] GET / => generated 113284 bytes in 560 msecs (HTTP/1.1 500) 6 headers in 187 bytes (1 switches on core 0)
SIGINT/SIGQUIT received...killing workers...
worker 1 buried after 1 seconds
goodbye to uWSGI.
VACUUM: pidfile removed.
VACUUM: unix socket /workspace/mbittest/tmp/MBIT.sock removed.
*** Starting uWSGI 2.0.19.1 (64bit) on [Sun Aug 29 21:31:34 2021] ***
compiled with version: 7.5.0 on 29 August 2021 18:36:23
os: Linux-4.4.0-1128-aws #142-Ubuntu SMP Fri Apr 16 12:42:33 UTC 2021
nodename: goorm
machine: x86_64
clock source: unix
pcre jit disabled
detected number of CPU cores: 2
current working directory: /workspace/mbittest
writing pidfile to /workspace/mbittest/tmp/MBIT.pid
detected binary path: /workspace/mbittest/SuperHong/bin/uwsgi
chdir() to /workspace/mbittest/
your memory page size is 4096 bytes
detected max file descriptor number: 1024
building mime-types dictionary from file /etc/mime.types...554 entry found
lock engine: pthread robust mutexes
thunder lock: disabled (you can enable it with --thunder-lock)
uwsgi socket 0 bound to UNIX address /workspace/mbittest/tmp/MBIT.sock fd 3
*** WARNING: you are running uWSGI as root !!! (use the --uid flag) *** 
Python version: 3.7.4 (default, Nov  4 2020, 10:17:35)  [GCC 7.4.0]
PEP 405 virtualenv detected: /workspace/mbittest/SuperHong/
Set PythonHome to /workspace/mbittest/SuperHong/
Python main interpreter initialized at 0x563de7bb3220
*** WARNING: you are running uWSGI as root !!! (use the --uid flag) *** 
python threads support enabled
your server socket listen backlog is limited to 100 connections
your mercy for graceful operations on workers is 60 seconds
mapped 145840 bytes (142 KB) for 1 cores
*** Operational MODE: single process ***
WSGI app 0 (mountpoint='') ready in 2 seconds on interpreter 0x563de7bb3220 pid: 17597 (default app)
*** WARNING: you are running uWSGI as root !!! (use the --uid flag) *** 
spawned uWSGI master process (pid: 17597)
spawned uWSGI worker 1 (pid: 17602, cores: 1)
subprocess 17598 exited with code 0
[pid: 17602|app: 0|req: 1/1] 172.17.0.1 () {58 vars in 2792 bytes} [Sun Aug 29 21:31:36 2021] GET / => generated 4097 bytes in 212 msecs (HTTP/1.1 200) 5 headers in 167 bytes (1 switches on core 0)
[pid: 17602|app: 0|req: 2/2] 172.17.0.1 () {58 vars in 2813 bytes} [Sun Aug 29 21:31:44 2021] GET /form => generated 0 bytes in 44 msecs (HTTP/1.1 301) 5 headers in 174 bytes (1 switches on core 0)
[pid: 17602|app: 0|req: 3/3] 172.17.0.1 () {58 vars in 2815 bytes} [Sun Aug 29 21:31:44 2021] GET /form/ => generated 70317 bytes in 650 msecs (HTTP/1.1 200) 7 headers in 350 bytes (1 switches on core 0)
[pid: 17602|app: 0|req: 4/4] 172.17.0.1 () {58 vars in 2815 bytes} [Sun Aug 29 21:31:51 2021] GET /form/ => generated 70317 bytes in 880 msecs (HTTP/1.1 200) 7 headers in 350 bytes (1 switches on core 0)
Internal Server Error: /submit/
Traceback (most recent call last):
  File "/workspace/mbittest/SuperHong/lib/python3.7/site-packages/django/urls/base.py", line 71, in reverse
    extra, resolver = resolver.namespace_dict[ns]
KeyError: 'main'

During handling of the above exception, another exception occurred:

Traceback (most recent call last):
  File "/workspace/mbittest/SuperHong/lib/python3.7/site-packages/django/core/handlers/exception.py", line 47, in inner
    response = get_response(request)
  File "/workspace/mbittest/SuperHong/lib/python3.7/site-packages/django/core/handlers/base.py", line 181, in _get_response
    response = wrapped_callback(request, *callback_args, **callback_kwargs)
  File "./main/views.py", line 81, in submit
    return redirect('main:result', developer_id = best_developer_id)
  File "/workspace/mbittest/SuperHong/lib/python3.7/site-packages/django/shortcuts.py", line 41, in redirect
    return redirect_class(resolve_url(to, *args, **kwargs))
  File "/workspace/mbittest/SuperHong/lib/python3.7/site-packages/django/shortcuts.py", line 130, in resolve_url
    return reverse(to, args=args, kwargs=kwargs)
  File "/workspace/mbittest/SuperHong/lib/python3.7/site-packages/django/urls/base.py", line 82, in reverse
    raise NoReverseMatch("%s is not a registered namespace" % key)
django.urls.exceptions.NoReverseMatch: 'main' is not a registered namespace
[pid: 17602|app: 0|req: 5/5] 172.17.0.1 () {66 vars in 3022 bytes} [Sun Aug 29 21:32:07 2021] POST /submit/ => generated 85169 bytes in 483 msecs (HTTP/1.1 500) 6 headers in 186 bytes (1 switches on core 0)
[pid: 17602|app: 0|req: 6/6] 172.17.0.1 () {60 vars in 2846 bytes} [Sun Aug 29 21:34:00 2021] GET /form/ => generated 70317 bytes in 904 msecs (HTTP/1.1 200) 7 headers in 350 bytes (1 switches on core 0)
SIGINT/SIGQUIT received...killing workers...
worker 1 buried after 1 seconds
goodbye to uWSGI.
VACUUM: pidfile removed.
VACUUM: unix socket /workspace/mbittest/tmp/MBIT.sock removed.
*** Starting uWSGI 2.0.19.1 (64bit) on [Sun Aug 29 21:34:04 2021] ***
compiled with version: 7.5.0 on 29 August 2021 18:36:23
os: Linux-4.4.0-1128-aws #142-Ubuntu SMP Fri Apr 16 12:42:33 UTC 2021
nodename: goorm
machine: x86_64
clock source: unix
pcre jit disabled
detected number of CPU cores: 2
current working directory: /workspace/mbittest
writing pidfile to /workspace/mbittest/tmp/MBIT.pid
detected binary path: /workspace/mbittest/SuperHong/bin/uwsgi
chdir() to /workspace/mbittest/
your memory page size is 4096 bytes
detected max file descriptor number: 1024
building mime-types dictionary from file /etc/mime.types...554 entry found
lock engine: pthread robust mutexes
thunder lock: disabled (you can enable it with --thunder-lock)
uwsgi socket 0 bound to UNIX address /workspace/mbittest/tmp/MBIT.sock fd 3
*** WARNING: you are running uWSGI as root !!! (use the --uid flag) *** 
Python version: 3.7.4 (default, Nov  4 2020, 10:17:35)  [GCC 7.4.0]
PEP 405 virtualenv detected: /workspace/mbittest/SuperHong/
Set PythonHome to /workspace/mbittest/SuperHong/
Python main interpreter initialized at 0x562b4c2f7220
*** WARNING: you are running uWSGI as root !!! (use the --uid flag) *** 
python threads support enabled
your server socket listen backlog is limited to 100 connections
your mercy for graceful operations on workers is 60 seconds
mapped 145840 bytes (142 KB) for 1 cores
*** Operational MODE: single process ***
WSGI app 0 (mountpoint='') ready in 2 seconds on interpreter 0x562b4c2f7220 pid: 17736 (default app)
*** WARNING: you are running uWSGI as root !!! (use the --uid flag) *** 
spawned uWSGI master process (pid: 17736)
spawned uWSGI worker 1 (pid: 17741, cores: 1)
subprocess 17737 exited with code 0
Internal Server Error: /
Traceback (most recent call last):
  File "/workspace/mbittest/SuperHong/lib/python3.7/site-packages/django/core/handlers/exception.py", line 47, in inner
    response = get_response(request)
  File "/workspace/mbittest/SuperHong/lib/python3.7/site-packages/django/core/handlers/base.py", line 167, in _get_response
    callback, callback_args, callback_kwargs = self.resolve_request(request)
  File "/workspace/mbittest/SuperHong/lib/python3.7/site-packages/django/core/handlers/base.py", line 290, in resolve_request
    resolver_match = resolver.resolve(request.path_info)
  File "/workspace/mbittest/SuperHong/lib/python3.7/site-packages/django/urls/resolvers.py", line 556, in resolve
    for pattern in self.url_patterns:
  File "/workspace/mbittest/SuperHong/lib/python3.7/site-packages/django/utils/functional.py", line 48, in __get__
    res = instance.__dict__[self.name] = self.func(instance)
  File "/workspace/mbittest/SuperHong/lib/python3.7/site-packages/django/urls/resolvers.py", line 598, in url_patterns
    patterns = getattr(self.urlconf_module, "urlpatterns", self.urlconf_module)
  File "/workspace/mbittest/SuperHong/lib/python3.7/site-packages/django/utils/functional.py", line 48, in __get__
    res = instance.__dict__[self.name] = self.func(instance)
  File "/workspace/mbittest/SuperHong/lib/python3.7/site-packages/django/urls/resolvers.py", line 591, in urlconf_module
    return import_module(self.urlconf_name)
  File "/usr/local/lib/python3.7/importlib/__init__.py", line 127, in import_module
    return _bootstrap._gcd_import(name[level:], package, level)
  File "<frozen importlib._bootstrap>", line 1006, in _gcd_import
  File "<frozen importlib._bootstrap>", line 983, in _find_and_load
  File "<frozen importlib._bootstrap>", line 967, in _find_and_load_unlocked
  File "<frozen importlib._bootstrap>", line 677, in _load_unlocked
  File "<frozen importlib._bootstrap_external>", line 728, in exec_module
  File "<frozen importlib._bootstrap>", line 219, in _call_with_frames_removed
  File "./MBIT/urls.py", line 11, in <module>
    path('result/<int:developer_id>', views.result, name='result'),
AttributeError: module 'main.views' has no attribute 'result'
[pid: 17741|app: 0|req: 1/1] 172.17.0.1 () {58 vars in 2792 bytes} [Sun Aug 29 21:34:06 2021] GET / => generated 113284 bytes in 543 msecs (HTTP/1.1 500) 6 headers in 187 bytes (1 switches on core 0)
SIGINT/SIGQUIT received...killing workers...
worker 1 buried after 1 seconds
goodbye to uWSGI.
VACUUM: pidfile removed.
VACUUM: unix socket /workspace/mbittest/tmp/MBIT.sock removed.
*** Starting uWSGI 2.0.19.1 (64bit) on [Sun Aug 29 21:35:20 2021] ***
compiled with version: 7.5.0 on 29 August 2021 18:36:23
os: Linux-4.4.0-1128-aws #142-Ubuntu SMP Fri Apr 16 12:42:33 UTC 2021
nodename: goorm
machine: x86_64
clock source: unix
pcre jit disabled
detected number of CPU cores: 2
current working directory: /workspace/mbittest
writing pidfile to /workspace/mbittest/tmp/MBIT.pid
detected binary path: /workspace/mbittest/SuperHong/bin/uwsgi
chdir() to /workspace/mbittest/
your memory page size is 4096 bytes
detected max file descriptor number: 1024
building mime-types dictionary from file /etc/mime.types...554 entry found
lock engine: pthread robust mutexes
thunder lock: disabled (you can enable it with --thunder-lock)
uwsgi socket 0 bound to UNIX address /workspace/mbittest/tmp/MBIT.sock fd 3
*** WARNING: you are running uWSGI as root !!! (use the --uid flag) *** 
Python version: 3.7.4 (default, Nov  4 2020, 10:17:35)  [GCC 7.4.0]
PEP 405 virtualenv detected: /workspace/mbittest/SuperHong/
Set PythonHome to /workspace/mbittest/SuperHong/
Python main interpreter initialized at 0x555ced2d2220
*** WARNING: you are running uWSGI as root !!! (use the --uid flag) *** 
python threads support enabled
your server socket listen backlog is limited to 100 connections
your mercy for graceful operations on workers is 60 seconds
mapped 145840 bytes (142 KB) for 1 cores
*** Operational MODE: single process ***
WSGI app 0 (mountpoint='') ready in 2 seconds on interpreter 0x555ced2d2220 pid: 17816 (default app)
*** WARNING: you are running uWSGI as root !!! (use the --uid flag) *** 
spawned uWSGI master process (pid: 17816)
spawned uWSGI worker 1 (pid: 17821, cores: 1)
subprocess 17817 exited with code 0
[pid: 17821|app: 0|req: 1/1] 172.17.0.1 () {58 vars in 2791 bytes} [Sun Aug 29 21:35:22 2021] GET / => generated 4097 bytes in 237 msecs (HTTP/1.1 200) 5 headers in 167 bytes (1 switches on core 0)
[pid: 17821|app: 0|req: 2/2] 172.17.0.1 () {58 vars in 2791 bytes} [Sun Aug 29 21:37:45 2021] GET / => generated 4097 bytes in 92 msecs (HTTP/1.1 200) 5 headers in 167 bytes (1 switches on core 0)
SIGINT/SIGQUIT received...killing workers...
worker 1 buried after 1 seconds
goodbye to uWSGI.
VACUUM: pidfile removed.
VACUUM: unix socket /workspace/mbittest/tmp/MBIT.sock removed.
*** Starting uWSGI 2.0.19.1 (64bit) on [Sun Aug 29 21:37:56 2021] ***
compiled with version: 7.5.0 on 29 August 2021 18:36:23
os: Linux-4.4.0-1128-aws #142-Ubuntu SMP Fri Apr 16 12:42:33 UTC 2021
nodename: goorm
machine: x86_64
clock source: unix
pcre jit disabled
detected number of CPU cores: 2
current working directory: /workspace/mbittest
writing pidfile to /workspace/mbittest/tmp/MBIT.pid
detected binary path: /workspace/mbittest/SuperHong/bin/uwsgi
chdir() to /workspace/mbittest/
your memory page size is 4096 bytes
detected max file descriptor number: 1024
building mime-types dictionary from file /etc/mime.types...554 entry found
lock engine: pthread robust mutexes
thunder lock: disabled (you can enable it with --thunder-lock)
uwsgi socket 0 bound to UNIX address /workspace/mbittest/tmp/MBIT.sock fd 3
*** WARNING: you are running uWSGI as root !!! (use the --uid flag) *** 
Python version: 3.7.4 (default, Nov  4 2020, 10:17:35)  [GCC 7.4.0]
PEP 405 virtualenv detected: /workspace/mbittest/SuperHong/
Set PythonHome to /workspace/mbittest/SuperHong/
Python main interpreter initialized at 0x564967933220
*** WARNING: you are running uWSGI as root !!! (use the --uid flag) *** 
python threads support enabled
your server socket listen backlog is limited to 100 connections
your mercy for graceful operations on workers is 60 seconds
mapped 145840 bytes (142 KB) for 1 cores
*** Operational MODE: single process ***
WSGI app 0 (mountpoint='') ready in 3 seconds on interpreter 0x564967933220 pid: 17961 (default app)
*** WARNING: you are running uWSGI as root !!! (use the --uid flag) *** 
spawned uWSGI master process (pid: 17961)
spawned uWSGI worker 1 (pid: 17967, cores: 1)
subprocess 17962 exited with code 0
Internal Server Error: /
Traceback (most recent call last):
  File "/workspace/mbittest/SuperHong/lib/python3.7/site-packages/django/core/handlers/exception.py", line 47, in inner
    response = get_response(request)
  File "/workspace/mbittest/SuperHong/lib/python3.7/site-packages/django/core/handlers/base.py", line 167, in _get_response
    callback, callback_args, callback_kwargs = self.resolve_request(request)
  File "/workspace/mbittest/SuperHong/lib/python3.7/site-packages/django/core/handlers/base.py", line 290, in resolve_request
    resolver_match = resolver.resolve(request.path_info)
  File "/workspace/mbittest/SuperHong/lib/python3.7/site-packages/django/urls/resolvers.py", line 556, in resolve
    for pattern in self.url_patterns:
  File "/workspace/mbittest/SuperHong/lib/python3.7/site-packages/django/utils/functional.py", line 48, in __get__
    res = instance.__dict__[self.name] = self.func(instance)
  File "/workspace/mbittest/SuperHong/lib/python3.7/site-packages/django/urls/resolvers.py", line 598, in url_patterns
    patterns = getattr(self.urlconf_module, "urlpatterns", self.urlconf_module)
  File "/workspace/mbittest/SuperHong/lib/python3.7/site-packages/django/utils/functional.py", line 48, in __get__
    res = instance.__dict__[self.name] = self.func(instance)
  File "/workspace/mbittest/SuperHong/lib/python3.7/site-packages/django/urls/resolvers.py", line 591, in urlconf_module
    return import_module(self.urlconf_name)
  File "/usr/local/lib/python3.7/importlib/__init__.py", line 127, in import_module
    return _bootstrap._gcd_import(name[level:], package, level)
  File "<frozen importlib._bootstrap>", line 1006, in _gcd_import
  File "<frozen importlib._bootstrap>", line 983, in _find_and_load
  File "<frozen importlib._bootstrap>", line 967, in _find_and_load_unlocked
  File "<frozen importlib._bootstrap>", line 677, in _load_unlocked
  File "<frozen importlib._bootstrap_external>", line 728, in exec_module
  File "<frozen importlib._bootstrap>", line 219, in _call_with_frames_removed
  File "./MBIT/urls.py", line 11, in <module>
    path('result/<int:developer_id>', views.result, name='result'),
AttributeError: module 'main.views' has no attribute 'result'
[pid: 17967|app: 0|req: 1/1] 172.17.0.1 () {58 vars in 2791 bytes} [Sun Aug 29 21:37:59 2021] GET / => generated 113283 bytes in 557 msecs (HTTP/1.1 500) 6 headers in 187 bytes (1 switches on core 0)
SIGINT/SIGQUIT received...killing workers...
worker 1 buried after 1 seconds
goodbye to uWSGI.
VACUUM: pidfile removed.
VACUUM: unix socket /workspace/mbittest/tmp/MBIT.sock removed.
*** Starting uWSGI 2.0.19.1 (64bit) on [Sun Aug 29 21:38:20 2021] ***
compiled with version: 7.5.0 on 29 August 2021 18:36:23
os: Linux-4.4.0-1128-aws #142-Ubuntu SMP Fri Apr 16 12:42:33 UTC 2021
nodename: goorm
machine: x86_64
clock source: unix
pcre jit disabled
detected number of CPU cores: 2
current working directory: /workspace/mbittest
writing pidfile to /workspace/mbittest/tmp/MBIT.pid
detected binary path: /workspace/mbittest/SuperHong/bin/uwsgi
chdir() to /workspace/mbittest/
your memory page size is 4096 bytes
detected max file descriptor number: 1024
building mime-types dictionary from file /etc/mime.types...554 entry found
lock engine: pthread robust mutexes
thunder lock: disabled (you can enable it with --thunder-lock)
uwsgi socket 0 bound to UNIX address /workspace/mbittest/tmp/MBIT.sock fd 3
*** WARNING: you are running uWSGI as root !!! (use the --uid flag) *** 
Python version: 3.7.4 (default, Nov  4 2020, 10:17:35)  [GCC 7.4.0]
PEP 405 virtualenv detected: /workspace/mbittest/SuperHong/
Set PythonHome to /workspace/mbittest/SuperHong/
Python main interpreter initialized at 0x55a931078220
*** WARNING: you are running uWSGI as root !!! (use the --uid flag) *** 
python threads support enabled
your server socket listen backlog is limited to 100 connections
your mercy for graceful operations on workers is 60 seconds
mapped 145840 bytes (142 KB) for 1 cores
*** Operational MODE: single process ***
WSGI app 0 (mountpoint='') ready in 2 seconds on interpreter 0x55a931078220 pid: 17999 (default app)
*** WARNING: you are running uWSGI as root !!! (use the --uid flag) *** 
spawned uWSGI master process (pid: 17999)
spawned uWSGI worker 1 (pid: 18004, cores: 1)
subprocess 18000 exited with code 0
Internal Server Error: /
Traceback (most recent call last):
  File "/workspace/mbittest/SuperHong/lib/python3.7/site-packages/django/core/handlers/exception.py", line 47, in inner
    response = get_response(request)
  File "/workspace/mbittest/SuperHong/lib/python3.7/site-packages/django/core/handlers/base.py", line 167, in _get_response
    callback, callback_args, callback_kwargs = self.resolve_request(request)
  File "/workspace/mbittest/SuperHong/lib/python3.7/site-packages/django/core/handlers/base.py", line 290, in resolve_request
    resolver_match = resolver.resolve(request.path_info)
  File "/workspace/mbittest/SuperHong/lib/python3.7/site-packages/django/urls/resolvers.py", line 556, in resolve
    for pattern in self.url_patterns:
  File "/workspace/mbittest/SuperHong/lib/python3.7/site-packages/django/utils/functional.py", line 48, in __get__
    res = instance.__dict__[self.name] = self.func(instance)
  File "/workspace/mbittest/SuperHong/lib/python3.7/site-packages/django/urls/resolvers.py", line 598, in url_patterns
    patterns = getattr(self.urlconf_module, "urlpatterns", self.urlconf_module)
  File "/workspace/mbittest/SuperHong/lib/python3.7/site-packages/django/utils/functional.py", line 48, in __get__
    res = instance.__dict__[self.name] = self.func(instance)
  File "/workspace/mbittest/SuperHong/lib/python3.7/site-packages/django/urls/resolvers.py", line 591, in urlconf_module
    return import_module(self.urlconf_name)
  File "/usr/local/lib/python3.7/importlib/__init__.py", line 127, in import_module
    return _bootstrap._gcd_import(name[level:], package, level)
  File "<frozen importlib._bootstrap>", line 1006, in _gcd_import
  File "<frozen importlib._bootstrap>", line 983, in _find_and_load
  File "<frozen importlib._bootstrap>", line 967, in _find_and_load_unlocked
  File "<frozen importlib._bootstrap>", line 677, in _load_unlocked
  File "<frozen importlib._bootstrap_external>", line 728, in exec_module
  File "<frozen importlib._bootstrap>", line 219, in _call_with_frames_removed
  File "./MBIT/urls.py", line 11, in <module>
    path('result/<int:developer_id>', views.result, name='result'),
AttributeError: module 'main.views' has no attribute 'result'
[pid: 18004|app: 0|req: 1/1] 172.17.0.1 () {58 vars in 2791 bytes} [Sun Aug 29 21:38:23 2021] GET / => generated 113283 bytes in 565 msecs (HTTP/1.1 500) 6 headers in 187 bytes (1 switches on core 0)
SIGINT/SIGQUIT received...killing workers...
worker 1 buried after 1 seconds
goodbye to uWSGI.
VACUUM: pidfile removed.
VACUUM: unix socket /workspace/mbittest/tmp/MBIT.sock removed.
*** Starting uWSGI 2.0.19.1 (64bit) on [Sun Aug 29 21:39:34 2021] ***
compiled with version: 7.5.0 on 29 August 2021 18:36:23
os: Linux-4.4.0-1128-aws #142-Ubuntu SMP Fri Apr 16 12:42:33 UTC 2021
nodename: goorm
machine: x86_64
clock source: unix
pcre jit disabled
detected number of CPU cores: 2
current working directory: /workspace/mbittest
writing pidfile to /workspace/mbittest/tmp/MBIT.pid
detected binary path: /workspace/mbittest/SuperHong/bin/uwsgi
chdir() to /workspace/mbittest/
your memory page size is 4096 bytes
detected max file descriptor number: 1024
building mime-types dictionary from file /etc/mime.types...554 entry found
lock engine: pthread robust mutexes
thunder lock: disabled (you can enable it with --thunder-lock)
uwsgi socket 0 bound to UNIX address /workspace/mbittest/tmp/MBIT.sock fd 3
*** WARNING: you are running uWSGI as root !!! (use the --uid flag) *** 
Python version: 3.7.4 (default, Nov  4 2020, 10:17:35)  [GCC 7.4.0]
PEP 405 virtualenv detected: /workspace/mbittest/SuperHong/
Set PythonHome to /workspace/mbittest/SuperHong/
Python main interpreter initialized at 0x55fdfa796220
*** WARNING: you are running uWSGI as root !!! (use the --uid flag) *** 
python threads support enabled
your server socket listen backlog is limited to 100 connections
your mercy for graceful operations on workers is 60 seconds
mapped 145840 bytes (142 KB) for 1 cores
*** Operational MODE: single process ***
WSGI app 0 (mountpoint='') ready in 2 seconds on interpreter 0x55fdfa796220 pid: 18077 (default app)
*** WARNING: you are running uWSGI as root !!! (use the --uid flag) *** 
spawned uWSGI master process (pid: 18077)
spawned uWSGI worker 1 (pid: 18082, cores: 1)
subprocess 18078 exited with code 0
[pid: 18082|app: 0|req: 1/1] 172.17.0.1 () {58 vars in 2792 bytes} [Sun Aug 29 21:39:36 2021] GET / => generated 4097 bytes in 208 msecs (HTTP/1.1 200) 5 headers in 167 bytes (1 switches on core 0)
SIGINT/SIGQUIT received...killing workers...
worker 1 buried after 1 seconds
goodbye to uWSGI.
VACUUM: pidfile removed.
VACUUM: unix socket /workspace/mbittest/tmp/MBIT.sock removed.
*** Starting uWSGI 2.0.19.1 (64bit) on [Sun Aug 29 21:40:23 2021] ***
compiled with version: 7.5.0 on 29 August 2021 18:36:23
os: Linux-4.4.0-1128-aws #142-Ubuntu SMP Fri Apr 16 12:42:33 UTC 2021
nodename: goorm
machine: x86_64
clock source: unix
pcre jit disabled
detected number of CPU cores: 2
current working directory: /workspace/mbittest
writing pidfile to /workspace/mbittest/tmp/MBIT.pid
detected binary path: /workspace/mbittest/SuperHong/bin/uwsgi
chdir() to /workspace/mbittest/
your memory page size is 4096 bytes
detected max file descriptor number: 1024
building mime-types dictionary from file /etc/mime.types...554 entry found
lock engine: pthread robust mutexes
thunder lock: disabled (you can enable it with --thunder-lock)
uwsgi socket 0 bound to UNIX address /workspace/mbittest/tmp/MBIT.sock fd 3
*** WARNING: you are running uWSGI as root !!! (use the --uid flag) *** 
Python version: 3.7.4 (default, Nov  4 2020, 10:17:35)  [GCC 7.4.0]
PEP 405 virtualenv detected: /workspace/mbittest/SuperHong/
Set PythonHome to /workspace/mbittest/SuperHong/
Python main interpreter initialized at 0x55f93ff00220
*** WARNING: you are running uWSGI as root !!! (use the --uid flag) *** 
python threads support enabled
your server socket listen backlog is limited to 100 connections
your mercy for graceful operations on workers is 60 seconds
mapped 145840 bytes (142 KB) for 1 cores
*** Operational MODE: single process ***
WSGI app 0 (mountpoint='') ready in 2 seconds on interpreter 0x55f93ff00220 pid: 18100 (default app)
*** WARNING: you are running uWSGI as root !!! (use the --uid flag) *** 
spawned uWSGI master process (pid: 18100)
spawned uWSGI worker 1 (pid: 18103, cores: 1)
subprocess 18101 exited with code 0
[pid: 18103|app: 0|req: 1/1] 172.17.0.1 () {58 vars in 2792 bytes} [Sun Aug 29 21:40:25 2021] GET / => generated 4097 bytes in 269 msecs (HTTP/1.1 200) 5 headers in 167 bytes (1 switches on core 0)
Internal Server Error: /
Traceback (most recent call last):
  File "/workspace/mbittest/SuperHong/lib/python3.7/site-packages/django/urls/base.py", line 71, in reverse
    extra, resolver = resolver.namespace_dict[ns]
KeyError: 'main'

During handling of the above exception, another exception occurred:

Traceback (most recent call last):
  File "/workspace/mbittest/SuperHong/lib/python3.7/site-packages/django/core/handlers/exception.py", line 47, in inner
    response = get_response(request)
  File "/workspace/mbittest/SuperHong/lib/python3.7/site-packages/django/core/handlers/base.py", line 181, in _get_response
    response = wrapped_callback(request, *callback_args, **callback_kwargs)
  File "./main/views.py", line 11, in index
    return render (request, 'index.html', context=context)
  File "/workspace/mbittest/SuperHong/lib/python3.7/site-packages/django/shortcuts.py", line 19, in render
    content = loader.render_to_string(template_name, context, request, using=using)
  File "/workspace/mbittest/SuperHong/lib/python3.7/site-packages/django/template/loader.py", line 62, in render_to_string
    return template.render(context, request)
  File "/workspace/mbittest/SuperHong/lib/python3.7/site-packages/django/template/backends/django.py", line 61, in render
    return self.template.render(context)
  File "/workspace/mbittest/SuperHong/lib/python3.7/site-packages/django/template/base.py", line 170, in render
    return self._render(context)
  File "/workspace/mbittest/SuperHong/lib/python3.7/site-packages/django/template/base.py", line 162, in _render
    return self.nodelist.render(context)
  File "/workspace/mbittest/SuperHong/lib/python3.7/site-packages/django/template/base.py", line 938, in render
    bit = node.render_annotated(context)
  File "/workspace/mbittest/SuperHong/lib/python3.7/site-packages/django/template/base.py", line 905, in render_annotated
    return self.render(context)
  File "/workspace/mbittest/SuperHong/lib/python3.7/site-packages/django/template/defaulttags.py", line 446, in render
    url = reverse(view_name, args=args, kwargs=kwargs, current_app=current_app)
  File "/workspace/mbittest/SuperHong/lib/python3.7/site-packages/django/urls/base.py", line 82, in reverse
    raise NoReverseMatch("%s is not a registered namespace" % key)
django.urls.exceptions.NoReverseMatch: 'main' is not a registered namespace
[pid: 18103|app: 0|req: 2/2] 172.17.0.1 () {58 vars in 2792 bytes} [Sun Aug 29 21:46:42 2021] GET / => generated 122899 bytes in 502 msecs (HTTP/1.1 500) 6 headers in 187 bytes (1 switches on core 0)
SIGINT/SIGQUIT received...killing workers...
worker 1 buried after 1 seconds
goodbye to uWSGI.
VACUUM: pidfile removed.
VACUUM: unix socket /workspace/mbittest/tmp/MBIT.sock removed.
*** Starting uWSGI 2.0.19.1 (64bit) on [Sun Aug 29 21:47:25 2021] ***
compiled with version: 7.5.0 on 29 August 2021 18:36:23
os: Linux-4.4.0-1128-aws #142-Ubuntu SMP Fri Apr 16 12:42:33 UTC 2021
nodename: goorm
machine: x86_64
clock source: unix
pcre jit disabled
detected number of CPU cores: 2
current working directory: /workspace/mbittest
writing pidfile to /workspace/mbittest/tmp/MBIT.pid
detected binary path: /workspace/mbittest/SuperHong/bin/uwsgi
chdir() to /workspace/mbittest/
your memory page size is 4096 bytes
detected max file descriptor number: 1024
building mime-types dictionary from file /etc/mime.types...554 entry found
lock engine: pthread robust mutexes
thunder lock: disabled (you can enable it with --thunder-lock)
uwsgi socket 0 bound to UNIX address /workspace/mbittest/tmp/MBIT.sock fd 3
*** WARNING: you are running uWSGI as root !!! (use the --uid flag) *** 
Python version: 3.7.4 (default, Nov  4 2020, 10:17:35)  [GCC 7.4.0]
PEP 405 virtualenv detected: /workspace/mbittest/SuperHong/
Set PythonHome to /workspace/mbittest/SuperHong/
Python main interpreter initialized at 0x5555ace61220
*** WARNING: you are running uWSGI as root !!! (use the --uid flag) *** 
python threads support enabled
your server socket listen backlog is limited to 100 connections
your mercy for graceful operations on workers is 60 seconds
mapped 145840 bytes (142 KB) for 1 cores
*** Operational MODE: single process ***
WSGI app 0 (mountpoint='') ready in 2 seconds on interpreter 0x5555ace61220 pid: 18119 (default app)
*** WARNING: you are running uWSGI as root !!! (use the --uid flag) *** 
spawned uWSGI master process (pid: 18119)
spawned uWSGI worker 1 (pid: 18122, cores: 1)
subprocess 18120 exited with code 0
Internal Server Error: /
Traceback (most recent call last):
  File "/workspace/mbittest/SuperHong/lib/python3.7/site-packages/django/core/handlers/exception.py", line 47, in inner
    response = get_response(request)
  File "/workspace/mbittest/SuperHong/lib/python3.7/site-packages/django/core/handlers/base.py", line 167, in _get_response
    callback, callback_args, callback_kwargs = self.resolve_request(request)
  File "/workspace/mbittest/SuperHong/lib/python3.7/site-packages/django/core/handlers/base.py", line 290, in resolve_request
    resolver_match = resolver.resolve(request.path_info)
  File "/workspace/mbittest/SuperHong/lib/python3.7/site-packages/django/urls/resolvers.py", line 556, in resolve
    for pattern in self.url_patterns:
  File "/workspace/mbittest/SuperHong/lib/python3.7/site-packages/django/utils/functional.py", line 48, in __get__
    res = instance.__dict__[self.name] = self.func(instance)
  File "/workspace/mbittest/SuperHong/lib/python3.7/site-packages/django/urls/resolvers.py", line 598, in url_patterns
    patterns = getattr(self.urlconf_module, "urlpatterns", self.urlconf_module)
  File "/workspace/mbittest/SuperHong/lib/python3.7/site-packages/django/utils/functional.py", line 48, in __get__
    res = instance.__dict__[self.name] = self.func(instance)
  File "/workspace/mbittest/SuperHong/lib/python3.7/site-packages/django/urls/resolvers.py", line 591, in urlconf_module
    return import_module(self.urlconf_name)
  File "/usr/local/lib/python3.7/importlib/__init__.py", line 127, in import_module
    return _bootstrap._gcd_import(name[level:], package, level)
  File "<frozen importlib._bootstrap>", line 1006, in _gcd_import
  File "<frozen importlib._bootstrap>", line 983, in _find_and_load
  File "<frozen importlib._bootstrap>", line 967, in _find_and_load_unlocked
  File "<frozen importlib._bootstrap>", line 677, in _load_unlocked
  File "<frozen importlib._bootstrap_external>", line 728, in exec_module
  File "<frozen importlib._bootstrap>", line 219, in _call_with_frames_removed
  File "./MBIT/urls.py", line 8, in <module>
    path('', include('main.urls')),
NameError: name 'include' is not defined
[pid: 18122|app: 0|req: 1/1] 172.17.0.1 () {58 vars in 2792 bytes} [Sun Aug 29 21:47:28 2021] GET / => generated 113009 bytes in 482 msecs (HTTP/1.1 500) 6 headers in 187 bytes (1 switches on core 0)
SIGINT/SIGQUIT received...killing workers...
worker 1 buried after 1 seconds
goodbye to uWSGI.
VACUUM: pidfile removed.
VACUUM: unix socket /workspace/mbittest/tmp/MBIT.sock removed.
*** Starting uWSGI 2.0.19.1 (64bit) on [Sun Aug 29 21:47:43 2021] ***
compiled with version: 7.5.0 on 29 August 2021 18:36:23
os: Linux-4.4.0-1128-aws #142-Ubuntu SMP Fri Apr 16 12:42:33 UTC 2021
nodename: goorm
machine: x86_64
clock source: unix
pcre jit disabled
detected number of CPU cores: 2
current working directory: /workspace/mbittest
writing pidfile to /workspace/mbittest/tmp/MBIT.pid
detected binary path: /workspace/mbittest/SuperHong/bin/uwsgi
chdir() to /workspace/mbittest/
your memory page size is 4096 bytes
detected max file descriptor number: 1024
building mime-types dictionary from file /etc/mime.types...554 entry found
lock engine: pthread robust mutexes
thunder lock: disabled (you can enable it with --thunder-lock)
uwsgi socket 0 bound to UNIX address /workspace/mbittest/tmp/MBIT.sock fd 3
*** WARNING: you are running uWSGI as root !!! (use the --uid flag) *** 
Python version: 3.7.4 (default, Nov  4 2020, 10:17:35)  [GCC 7.4.0]
PEP 405 virtualenv detected: /workspace/mbittest/SuperHong/
Set PythonHome to /workspace/mbittest/SuperHong/
Python main interpreter initialized at 0x55611f83a220
*** WARNING: you are running uWSGI as root !!! (use the --uid flag) *** 
python threads support enabled
your server socket listen backlog is limited to 100 connections
your mercy for graceful operations on workers is 60 seconds
mapped 145840 bytes (142 KB) for 1 cores
*** Operational MODE: single process ***
WSGI app 0 (mountpoint='') ready in 2 seconds on interpreter 0x55611f83a220 pid: 18138 (default app)
*** WARNING: you are running uWSGI as root !!! (use the --uid flag) *** 
spawned uWSGI master process (pid: 18138)
spawned uWSGI worker 1 (pid: 18141, cores: 1)
subprocess 18139 exited with code 0
Internal Server Error: /
Traceback (most recent call last):
  File "/workspace/mbittest/SuperHong/lib/python3.7/site-packages/django/core/handlers/exception.py", line 47, in inner
    response = get_response(request)
  File "/workspace/mbittest/SuperHong/lib/python3.7/site-packages/django/core/handlers/base.py", line 167, in _get_response
    callback, callback_args, callback_kwargs = self.resolve_request(request)
  File "/workspace/mbittest/SuperHong/lib/python3.7/site-packages/django/core/handlers/base.py", line 290, in resolve_request
    resolver_match = resolver.resolve(request.path_info)
  File "/workspace/mbittest/SuperHong/lib/python3.7/site-packages/django/urls/resolvers.py", line 556, in resolve
    for pattern in self.url_patterns:
  File "/workspace/mbittest/SuperHong/lib/python3.7/site-packages/django/utils/functional.py", line 48, in __get__
    res = instance.__dict__[self.name] = self.func(instance)
  File "/workspace/mbittest/SuperHong/lib/python3.7/site-packages/django/urls/resolvers.py", line 598, in url_patterns
    patterns = getattr(self.urlconf_module, "urlpatterns", self.urlconf_module)
  File "/workspace/mbittest/SuperHong/lib/python3.7/site-packages/django/utils/functional.py", line 48, in __get__
    res = instance.__dict__[self.name] = self.func(instance)
  File "/workspace/mbittest/SuperHong/lib/python3.7/site-packages/django/urls/resolvers.py", line 591, in urlconf_module
    return import_module(self.urlconf_name)
  File "/usr/local/lib/python3.7/importlib/__init__.py", line 127, in import_module
    return _bootstrap._gcd_import(name[level:], package, level)
  File "<frozen importlib._bootstrap>", line 1006, in _gcd_import
  File "<frozen importlib._bootstrap>", line 983, in _find_and_load
  File "<frozen importlib._bootstrap>", line 967, in _find_and_load_unlocked
  File "<frozen importlib._bootstrap>", line 677, in _load_unlocked
  File "<frozen importlib._bootstrap_external>", line 728, in exec_module
  File "<frozen importlib._bootstrap>", line 219, in _call_with_frames_removed
  File "./MBIT/urls.py", line 8, in <module>
    path('', include('main.urls')),
NameError: name 'include' is not defined
[pid: 18141|app: 0|req: 1/1] 172.17.0.1 () {58 vars in 2792 bytes} [Sun Aug 29 21:47:45 2021] GET / => generated 113009 bytes in 507 msecs (HTTP/1.1 500) 6 headers in 187 bytes (1 switches on core 0)
SIGINT/SIGQUIT received...killing workers...
worker 1 buried after 1 seconds
goodbye to uWSGI.
VACUUM: pidfile removed.
VACUUM: unix socket /workspace/mbittest/tmp/MBIT.sock removed.
*** Starting uWSGI 2.0.19.1 (64bit) on [Sun Aug 29 21:48:21 2021] ***
compiled with version: 7.5.0 on 29 August 2021 18:36:23
os: Linux-4.4.0-1128-aws #142-Ubuntu SMP Fri Apr 16 12:42:33 UTC 2021
nodename: goorm
machine: x86_64
clock source: unix
pcre jit disabled
detected number of CPU cores: 2
current working directory: /workspace/mbittest
writing pidfile to /workspace/mbittest/tmp/MBIT.pid
detected binary path: /workspace/mbittest/SuperHong/bin/uwsgi
chdir() to /workspace/mbittest/
your memory page size is 4096 bytes
detected max file descriptor number: 1024
building mime-types dictionary from file /etc/mime.types...554 entry found
lock engine: pthread robust mutexes
thunder lock: disabled (you can enable it with --thunder-lock)
uwsgi socket 0 bound to UNIX address /workspace/mbittest/tmp/MBIT.sock fd 3
*** WARNING: you are running uWSGI as root !!! (use the --uid flag) *** 
Python version: 3.7.4 (default, Nov  4 2020, 10:17:35)  [GCC 7.4.0]
PEP 405 virtualenv detected: /workspace/mbittest/SuperHong/
Set PythonHome to /workspace/mbittest/SuperHong/
Python main interpreter initialized at 0x56531b5b1220
*** WARNING: you are running uWSGI as root !!! (use the --uid flag) *** 
python threads support enabled
your server socket listen backlog is limited to 100 connections
your mercy for graceful operations on workers is 60 seconds
mapped 145840 bytes (142 KB) for 1 cores
*** Operational MODE: single process ***
WSGI app 0 (mountpoint='') ready in 2 seconds on interpreter 0x56531b5b1220 pid: 18157 (default app)
*** WARNING: you are running uWSGI as root !!! (use the --uid flag) *** 
spawned uWSGI master process (pid: 18157)
spawned uWSGI worker 1 (pid: 18160, cores: 1)
subprocess 18158 exited with code 0
[pid: 18160|app: 0|req: 1/1] 172.17.0.1 () {58 vars in 2792 bytes} [Sun Aug 29 21:48:23 2021] GET / => generated 4097 bytes in 212 msecs (HTTP/1.1 200) 5 headers in 167 bytes (1 switches on core 0)
SIGINT/SIGQUIT received...killing workers...
worker 1 buried after 1 seconds
goodbye to uWSGI.
VACUUM: pidfile removed.
VACUUM: unix socket /workspace/mbittest/tmp/MBIT.sock removed.
*** Starting uWSGI 2.0.19.1 (64bit) on [Sun Aug 29 21:48:36 2021] ***
compiled with version: 7.5.0 on 29 August 2021 18:36:23
os: Linux-4.4.0-1128-aws #142-Ubuntu SMP Fri Apr 16 12:42:33 UTC 2021
nodename: goorm
machine: x86_64
clock source: unix
pcre jit disabled
detected number of CPU cores: 2
current working directory: /workspace/mbittest
writing pidfile to /workspace/mbittest/tmp/MBIT.pid
detected binary path: /workspace/mbittest/SuperHong/bin/uwsgi
chdir() to /workspace/mbittest/
your memory page size is 4096 bytes
detected max file descriptor number: 1024
building mime-types dictionary from file /etc/mime.types...554 entry found
lock engine: pthread robust mutexes
thunder lock: disabled (you can enable it with --thunder-lock)
uwsgi socket 0 bound to UNIX address /workspace/mbittest/tmp/MBIT.sock fd 3
*** WARNING: you are running uWSGI as root !!! (use the --uid flag) *** 
Python version: 3.7.4 (default, Nov  4 2020, 10:17:35)  [GCC 7.4.0]
PEP 405 virtualenv detected: /workspace/mbittest/SuperHong/
Set PythonHome to /workspace/mbittest/SuperHong/
Python main interpreter initialized at 0x55d5908de220
*** WARNING: you are running uWSGI as root !!! (use the --uid flag) *** 
python threads support enabled
your server socket listen backlog is limited to 100 connections
your mercy for graceful operations on workers is 60 seconds
mapped 145840 bytes (142 KB) for 1 cores
*** Operational MODE: single process ***
WSGI app 0 (mountpoint='') ready in 2 seconds on interpreter 0x55d5908de220 pid: 18176 (default app)
*** WARNING: you are running uWSGI as root !!! (use the --uid flag) *** 
spawned uWSGI master process (pid: 18176)
spawned uWSGI worker 1 (pid: 18179, cores: 1)
subprocess 18177 exited with code 0
[pid: 18179|app: 0|req: 1/1] 172.17.0.1 () {58 vars in 2792 bytes} [Sun Aug 29 21:48:38 2021] GET / => generated 4098 bytes in 232 msecs (HTTP/1.1 200) 5 headers in 167 bytes (1 switches on core 0)
[pid: 18179|app: 0|req: 2/2] 172.17.0.1 () {58 vars in 2815 bytes} [Sun Aug 29 21:48:40 2021] GET /form/ => generated 70317 bytes in 637 msecs (HTTP/1.1 200) 7 headers in 350 bytes (1 switches on core 0)
SIGINT/SIGQUIT received...killing workers...
worker 1 buried after 1 seconds
goodbye to uWSGI.
VACUUM: pidfile removed.
VACUUM: unix socket /workspace/mbittest/tmp/MBIT.sock removed.
*** Starting uWSGI 2.0.19.1 (64bit) on [Sun Aug 29 21:51:10 2021] ***
compiled with version: 7.5.0 on 29 August 2021 18:36:23
os: Linux-4.4.0-1128-aws #142-Ubuntu SMP Fri Apr 16 12:42:33 UTC 2021
nodename: goorm
machine: x86_64
clock source: unix
pcre jit disabled
detected number of CPU cores: 2
current working directory: /workspace/mbittest
writing pidfile to /workspace/mbittest/tmp/MBIT.pid
detected binary path: /workspace/mbittest/SuperHong/bin/uwsgi
chdir() to /workspace/mbittest/
your memory page size is 4096 bytes
detected max file descriptor number: 1024
building mime-types dictionary from file /etc/mime.types...554 entry found
lock engine: pthread robust mutexes
thunder lock: disabled (you can enable it with --thunder-lock)
uwsgi socket 0 bound to UNIX address /workspace/mbittest/tmp/MBIT.sock fd 3
*** WARNING: you are running uWSGI as root !!! (use the --uid flag) *** 
Python version: 3.7.4 (default, Nov  4 2020, 10:17:35)  [GCC 7.4.0]
PEP 405 virtualenv detected: /workspace/mbittest/SuperHong/
Set PythonHome to /workspace/mbittest/SuperHong/
Python main interpreter initialized at 0x563e57d1a220
*** WARNING: you are running uWSGI as root !!! (use the --uid flag) *** 
python threads support enabled
your server socket listen backlog is limited to 100 connections
your mercy for graceful operations on workers is 60 seconds
mapped 145840 bytes (142 KB) for 1 cores
*** Operational MODE: single process ***
WSGI app 0 (mountpoint='') ready in 2 seconds on interpreter 0x563e57d1a220 pid: 18195 (default app)
*** WARNING: you are running uWSGI as root !!! (use the --uid flag) *** 
spawned uWSGI master process (pid: 18195)
spawned uWSGI worker 1 (pid: 18198, cores: 1)
subprocess 18196 exited with code 0
[pid: 18198|app: 0|req: 1/1] 172.17.0.1 () {58 vars in 2791 bytes} [Sun Aug 29 21:51:13 2021] GET / => generated 4098 bytes in 212 msecs (HTTP/1.1 200) 5 headers in 167 bytes (1 switches on core 0)
[pid: 18198|app: 0|req: 2/2] 172.17.0.1 () {58 vars in 2814 bytes} [Sun Aug 29 21:51:13 2021] GET /form/ => generated 70317 bytes in 669 msecs (HTTP/1.1 200) 7 headers in 350 bytes (1 switches on core 0)
[pid: 18198|app: 0|req: 3/3] 172.17.0.1 () {66 vars in 3021 bytes} [Sun Aug 29 21:51:29 2021] POST /submit/ => generated 0 bytes in 84 msecs (HTTP/1.1 302) 6 headers in 189 bytes (1 switches on core 0)
[pid: 18198|app: 0|req: 4/4] 172.17.0.1 () {60 vars in 2858 bytes} [Sun Aug 29 21:51:30 2021] GET /result/2/ => generated 12438 bytes in 6 msecs (HTTP/1.1 200) 5 headers in 168 bytes (1 switches on core 0)
[pid: 18198|app: 0|req: 5/5] 172.17.0.1 () {60 vars in 2858 bytes} [Sun Aug 29 21:51:32 2021] GET /result/2/ => generated 12438 bytes in 30 msecs (HTTP/1.1 200) 5 headers in 168 bytes (1 switches on core 0)
[pid: 18198|app: 0|req: 6/6] 172.17.0.1 () {60 vars in 2858 bytes} [Sun Aug 29 21:51:32 2021] GET /result/2/ => generated 12438 bytes in 73 msecs (HTTP/1.1 200) 5 headers in 168 bytes (1 switches on core 0)
[pid: 18198|app: 0|req: 7/7] 172.17.0.1 () {60 vars in 2858 bytes} [Sun Aug 29 21:51:32 2021] GET /result/2/ => generated 12438 bytes in 79 msecs (HTTP/1.1 200) 5 headers in 168 bytes (1 switches on core 0)
[pid: 18198|app: 0|req: 8/8] 172.17.0.1 () {60 vars in 2858 bytes} [Sun Aug 29 21:51:33 2021] GET /result/2/ => generated 12438 bytes in 7 msecs (HTTP/1.1 200) 5 headers in 168 bytes (1 switches on core 0)
[pid: 18198|app: 0|req: 9/9] 172.17.0.1 () {60 vars in 2858 bytes} [Sun Aug 29 21:51:33 2021] GET /result/2/ => generated 12438 bytes in 7 msecs (HTTP/1.1 200) 5 headers in 168 bytes (1 switches on core 0)
[pid: 18198|app: 0|req: 10/10] 172.17.0.1 () {60 vars in 2858 bytes} [Sun Aug 29 21:51:33 2021] GET /result/2/ => generated 12438 bytes in 8 msecs (HTTP/1.1 200) 5 headers in 168 bytes (1 switches on core 0)
[pid: 18198|app: 0|req: 11/11] 172.17.0.1 () {56 vars in 2745 bytes} [Sun Aug 29 21:51:40 2021] GET / => generated 4098 bytes in 77 msecs (HTTP/1.1 200) 5 headers in 167 bytes (1 switches on core 0)
SIGINT/SIGQUIT received...killing workers...
worker 1 buried after 1 seconds
goodbye to uWSGI.
VACUUM: pidfile removed.
VACUUM: unix socket /workspace/mbittest/tmp/MBIT.sock removed.
*** Starting uWSGI 2.0.19.1 (64bit) on [Sun Aug 29 21:57:30 2021] ***
compiled with version: 7.5.0 on 29 August 2021 18:36:23
os: Linux-4.4.0-1128-aws #142-Ubuntu SMP Fri Apr 16 12:42:33 UTC 2021
nodename: goorm
machine: x86_64
clock source: unix
pcre jit disabled
detected number of CPU cores: 2
current working directory: /workspace/mbittest
writing pidfile to /workspace/mbittest/tmp/MBIT.pid
detected binary path: /workspace/mbittest/SuperHong/bin/uwsgi
chdir() to /workspace/mbittest/
your memory page size is 4096 bytes
detected max file descriptor number: 1024
building mime-types dictionary from file /etc/mime.types...554 entry found
lock engine: pthread robust mutexes
thunder lock: disabled (you can enable it with --thunder-lock)
uwsgi socket 0 bound to UNIX address /workspace/mbittest/tmp/MBIT.sock fd 3
*** WARNING: you are running uWSGI as root !!! (use the --uid flag) *** 
Python version: 3.7.4 (default, Nov  4 2020, 10:17:35)  [GCC 7.4.0]
PEP 405 virtualenv detected: /workspace/mbittest/SuperHong/
Set PythonHome to /workspace/mbittest/SuperHong/
Python main interpreter initialized at 0x55f9bb416220
*** WARNING: you are running uWSGI as root !!! (use the --uid flag) *** 
python threads support enabled
your server socket listen backlog is limited to 100 connections
your mercy for graceful operations on workers is 60 seconds
mapped 145840 bytes (142 KB) for 1 cores
*** Operational MODE: single process ***
WSGI app 0 (mountpoint='') ready in 2 seconds on interpreter 0x55f9bb416220 pid: 18214 (default app)
*** WARNING: you are running uWSGI as root !!! (use the --uid flag) *** 
spawned uWSGI master process (pid: 18214)
spawned uWSGI worker 1 (pid: 18217, cores: 1)
subprocess 18215 exited with code 0
Internal Server Error: /
Traceback (most recent call last):
  File "/workspace/mbittest/SuperHong/lib/python3.7/site-packages/django/core/handlers/exception.py", line 47, in inner
    response = get_response(request)
  File "/workspace/mbittest/SuperHong/lib/python3.7/site-packages/django/core/handlers/base.py", line 181, in _get_response
    response = wrapped_callback(request, *callback_args, **callback_kwargs)
  File "./main/views.py", line 11, in index
    return render (request, 'main/index.html', context=context)
  File "/workspace/mbittest/SuperHong/lib/python3.7/site-packages/django/shortcuts.py", line 19, in render
    content = loader.render_to_string(template_name, context, request, using=using)
  File "/workspace/mbittest/SuperHong/lib/python3.7/site-packages/django/template/loader.py", line 61, in render_to_string
    template = get_template(template_name, using=using)
  File "/workspace/mbittest/SuperHong/lib/python3.7/site-packages/django/template/loader.py", line 15, in get_template
    return engine.get_template(template_name)
  File "/workspace/mbittest/SuperHong/lib/python3.7/site-packages/django/template/backends/django.py", line 34, in get_template
    return Template(self.engine.get_template(template_name), self)
  File "/workspace/mbittest/SuperHong/lib/python3.7/site-packages/django/template/engine.py", line 143, in get_template
    template, origin = self.find_template(template_name)
  File "/workspace/mbittest/SuperHong/lib/python3.7/site-packages/django/template/engine.py", line 125, in find_template
    template = loader.get_template(name, skip=skip)
  File "/workspace/mbittest/SuperHong/lib/python3.7/site-packages/django/template/loaders/base.py", line 30, in get_template
    contents, origin, origin.template_name, self.engine,
  File "/workspace/mbittest/SuperHong/lib/python3.7/site-packages/django/template/base.py", line 155, in __init__
    self.nodelist = self.compile_nodelist()
  File "/workspace/mbittest/SuperHong/lib/python3.7/site-packages/django/template/base.py", line 193, in compile_nodelist
    return parser.parse()
  File "/workspace/mbittest/SuperHong/lib/python3.7/site-packages/django/template/base.py", line 479, in parse
    self.extend_nodelist(nodelist, compiled_result, token)
  File "/workspace/mbittest/SuperHong/lib/python3.7/site-packages/django/template/base.py", line 497, in extend_nodelist
    token, '%r must be the first tag in the template.' % node,
django.template.exceptions.TemplateSyntaxError: <ExtendsNode: extends 'main/base.html'> must be the first tag in the template.
[pid: 18217|app: 0|req: 1/1] 172.17.0.1 () {58 vars in 2792 bytes} [Sun Aug 29 21:57:32 2021] GET / => generated 131550 bytes in 682 msecs (HTTP/1.1 500) 6 headers in 187 bytes (1 switches on core 0)
[pid: 18217|app: 0|req: 2/2] 172.17.0.1 () {60 vars in 2823 bytes} [Sun Aug 29 21:59:00 2021] GET / => generated 2016 bytes in 86 msecs (HTTP/1.1 200) 5 headers in 167 bytes (1 switches on core 0)
[pid: 18217|app: 0|req: 3/3] 172.17.0.1 () {60 vars in 2823 bytes} [Sun Aug 29 21:59:01 2021] GET / => generated 2016 bytes in 63 msecs (HTTP/1.1 200) 5 headers in 167 bytes (1 switches on core 0)
[pid: 18217|app: 0|req: 4/4] 172.17.0.1 () {58 vars in 2792 bytes} [Sun Aug 29 21:59:14 2021] GET / => generated 2016 bytes in 24 msecs (HTTP/1.1 200) 5 headers in 167 bytes (1 switches on core 0)
[pid: 18217|app: 0|req: 5/5] 172.17.0.1 () {58 vars in 2792 bytes} [Sun Aug 29 22:00:13 2021] GET / => generated 2016 bytes in 86 msecs (HTTP/1.1 200) 5 headers in 167 bytes (1 switches on core 0)
[pid: 18217|app: 0|req: 6/6] 172.17.0.1 () {58 vars in 2815 bytes} [Sun Aug 29 22:00:14 2021] GET /form/ => generated 35083 bytes in 398 msecs (HTTP/1.1 200) 7 headers in 350 bytes (1 switches on core 0)
[pid: 18217|app: 0|req: 7/7] 172.17.0.1 () {66 vars in 3022 bytes} [Sun Aug 29 22:00:32 2021] POST /submit/ => generated 0 bytes in 115 msecs (HTTP/1.1 302) 6 headers in 189 bytes (1 switches on core 0)
[pid: 18217|app: 0|req: 8/8] 172.17.0.1 () {60 vars in 2859 bytes} [Sun Aug 29 22:00:32 2021] GET /result/3/ => generated 12452 bytes in 13 msecs (HTTP/1.1 200) 5 headers in 168 bytes (1 switches on core 0)
[pid: 18217|app: 0|req: 9/9] 172.17.0.1 () {58 vars in 2791 bytes} [Sun Aug 29 22:01:46 2021] GET / => generated 2016 bytes in 7 msecs (HTTP/1.1 200) 5 headers in 167 bytes (1 switches on core 0)
[pid: 18217|app: 0|req: 10/10] 172.17.0.1 () {60 vars in 2822 bytes} [Sun Aug 29 22:01:47 2021] GET / => generated 2016 bytes in 15 msecs (HTTP/1.1 200) 5 headers in 167 bytes (1 switches on core 0)
[pid: 18217|app: 0|req: 11/11] 172.17.0.1 () {60 vars in 2822 bytes} [Sun Aug 29 22:01:47 2021] GET / => generated 2016 bytes in 80 msecs (HTTP/1.1 200) 5 headers in 167 bytes (1 switches on core 0)
[pid: 18217|app: 0|req: 12/12] 172.17.0.1 () {60 vars in 2822 bytes} [Sun Aug 29 22:01:47 2021] GET / => generated 2016 bytes in 13 msecs (HTTP/1.1 200) 5 headers in 167 bytes (1 switches on core 0)
[pid: 18217|app: 0|req: 13/13] 172.17.0.1 () {60 vars in 2822 bytes} [Sun Aug 29 22:01:48 2021] GET / => generated 2016 bytes in 35 msecs (HTTP/1.1 200) 5 headers in 167 bytes (1 switches on core 0)
[pid: 18217|app: 0|req: 14/14] 172.17.0.1 () {60 vars in 2822 bytes} [Sun Aug 29 22:01:48 2021] GET / => generated 2016 bytes in 11 msecs (HTTP/1.1 200) 5 headers in 167 bytes (1 switches on core 0)
[pid: 18217|app: 0|req: 15/15] 172.17.0.1 () {58 vars in 2791 bytes} [Sun Aug 29 22:01:58 2021] GET / => generated 2016 bytes in 19 msecs (HTTP/1.1 200) 5 headers in 167 bytes (1 switches on core 0)
[pid: 18217|app: 0|req: 16/16] 172.17.0.1 () {58 vars in 2814 bytes} [Sun Aug 29 22:01:59 2021] GET /form/ => generated 35097 bytes in 304 msecs (HTTP/1.1 200) 7 headers in 350 bytes (1 switches on core 0)
[pid: 18217|app: 0|req: 17/17] 172.17.0.1 () {58 vars in 2792 bytes} [Sun Aug 29 22:04:01 2021] GET / => generated 2016 bytes in 15 msecs (HTTP/1.1 200) 5 headers in 167 bytes (1 switches on core 0)
[pid: 18217|app: 0|req: 18/18] 172.17.0.1 () {58 vars in 2815 bytes} [Sun Aug 29 22:04:03 2021] GET /form/ => generated 35081 bytes in 255 msecs (HTTP/1.1 200) 7 headers in 350 bytes (1 switches on core 0)
[pid: 18217|app: 0|req: 19/19] 172.17.0.1 () {56 vars in 2762 bytes} [Sun Aug 29 22:04:14 2021] GET /result/2 => generated 0 bytes in 1 msecs (HTTP/1.1 301) 5 headers in 178 bytes (1 switches on core 0)
[pid: 18217|app: 0|req: 20/20] 172.17.0.1 () {56 vars in 2764 bytes} [Sun Aug 29 22:04:14 2021] GET /result/2/ => generated 7673 bytes in 19 msecs (HTTP/1.1 200) 5 headers in 167 bytes (1 switches on core 0)
Sun Aug 29 22:06:39 2021 - *** PAUSE (press start to resume, if you do not have a joypad send SIGTSTP) ***
Sun Aug 29 22:06:39 2021 - *** worker 1 suspended ***
SIGINT/SIGQUIT received...killing workers...
worker 1 buried after 1 seconds
goodbye to uWSGI.
VACUUM: pidfile removed.
VACUUM: unix socket /workspace/mbittest/tmp/MBIT.sock removed.
*** Starting uWSGI 2.0.19.1 (64bit) on [Sun Aug 29 22:13:54 2021] ***
compiled with version: 7.5.0 on 29 August 2021 18:36:23
os: Linux-4.4.0-1128-aws #142-Ubuntu SMP Fri Apr 16 12:42:33 UTC 2021
nodename: goorm
machine: x86_64
clock source: unix
pcre jit disabled
detected number of CPU cores: 2
current working directory: /workspace/mbittest
writing pidfile to /workspace/mbittest/tmp/MBIT.pid
detected binary path: /workspace/mbittest/SuperHong/bin/uwsgi
chdir() to /workspace/mbittest/
your memory page size is 4096 bytes
detected max file descriptor number: 1024
building mime-types dictionary from file /etc/mime.types...554 entry found
lock engine: pthread robust mutexes
thunder lock: disabled (you can enable it with --thunder-lock)
uwsgi socket 0 bound to UNIX address /workspace/mbittest/tmp/MBIT.sock fd 3
*** WARNING: you are running uWSGI as root !!! (use the --uid flag) *** 
Python version: 3.7.4 (default, Nov  4 2020, 10:17:35)  [GCC 7.4.0]
PEP 405 virtualenv detected: /workspace/mbittest/SuperHong/
Set PythonHome to /workspace/mbittest/SuperHong/
Python main interpreter initialized at 0x56070be87220
*** WARNING: you are running uWSGI as root !!! (use the --uid flag) *** 
python threads support enabled
your server socket listen backlog is limited to 100 connections
your mercy for graceful operations on workers is 60 seconds
mapped 145840 bytes (142 KB) for 1 cores
*** Operational MODE: single process ***
WSGI app 0 (mountpoint='') ready in 2 seconds on interpreter 0x56070be87220 pid: 18259 (default app)
*** WARNING: you are running uWSGI as root !!! (use the --uid flag) *** 
spawned uWSGI master process (pid: 18259)
spawned uWSGI worker 1 (pid: 18262, cores: 1)
subprocess 18260 exited with code 0
[pid: 18262|app: 0|req: 1/1] 172.17.0.1 () {58 vars in 2791 bytes} [Sun Aug 29 22:13:56 2021] GET / => generated 2019 bytes in 257 msecs (HTTP/1.1 200) 5 headers in 167 bytes (1 switches on core 0)
[pid: 18262|app: 0|req: 2/2] 172.17.0.1 () {58 vars in 2814 bytes} [Sun Aug 29 22:13:57 2021] GET /form/ => generated 34779 bytes in 412 msecs (HTTP/1.1 200) 7 headers in 350 bytes (1 switches on core 0)
Internal Server Error: /submit/
Traceback (most recent call last):
  File "/workspace/mbittest/SuperHong/lib/python3.7/site-packages/django/core/handlers/exception.py", line 47, in inner
    response = get_response(request)
  File "/workspace/mbittest/SuperHong/lib/python3.7/site-packages/django/core/handlers/base.py", line 181, in _get_response
    response = wrapped_callback(request, *callback_args, **callback_kwargs)
  File "./main/views.py", line 34, in submit
    developer_id = int(request.POST[f'question-{n}'][0])
IndexError: string index out of range
[pid: 18262|app: 0|req: 3/3] 172.17.0.1 () {66 vars in 3021 bytes} [Sun Aug 29 22:14:13 2021] POST /submit/ => generated 63317 bytes in 268 msecs (HTTP/1.1 500) 6 headers in 186 bytes (1 switches on core 0)
[pid: 18262|app: 0|req: 4/4] 172.17.0.1 () {58 vars in 2792 bytes} [Sun Aug 29 22:17:55 2021] GET / => generated 2019 bytes in 100 msecs (HTTP/1.1 200) 5 headers in 167 bytes (1 switches on core 0)
[pid: 18262|app: 0|req: 5/5] 172.17.0.1 () {58 vars in 2815 bytes} [Sun Aug 29 22:17:57 2021] GET /form/ => generated 34779 bytes in 699 msecs (HTTP/1.1 200) 7 headers in 350 bytes (1 switches on core 0)
[pid: 18262|app: 0|req: 6/6] 172.17.0.1 () {66 vars in 3022 bytes} [Sun Aug 29 22:18:11 2021] POST /submit/ => generated 0 bytes in 57 msecs (HTTP/1.1 302) 6 headers in 189 bytes (1 switches on core 0)
Internal Server Error: /result/5/
Traceback (most recent call last):
  File "/workspace/mbittest/SuperHong/lib/python3.7/site-packages/django/core/handlers/exception.py", line 47, in inner
    response = get_response(request)
  File "/workspace/mbittest/SuperHong/lib/python3.7/site-packages/django/core/handlers/base.py", line 181, in _get_response
    response = wrapped_callback(request, *callback_args, **callback_kwargs)
  File "./main/views.py", line 58, in result
    return render(request, 'main/result.html', context=context)
  File "/workspace/mbittest/SuperHong/lib/python3.7/site-packages/django/shortcuts.py", line 19, in render
    content = loader.render_to_string(template_name, context, request, using=using)
  File "/workspace/mbittest/SuperHong/lib/python3.7/site-packages/django/template/loader.py", line 61, in render_to_string
    template = get_template(template_name, using=using)
  File "/workspace/mbittest/SuperHong/lib/python3.7/site-packages/django/template/loader.py", line 15, in get_template
    return engine.get_template(template_name)
  File "/workspace/mbittest/SuperHong/lib/python3.7/site-packages/django/template/backends/django.py", line 34, in get_template
    return Template(self.engine.get_template(template_name), self)
  File "/workspace/mbittest/SuperHong/lib/python3.7/site-packages/django/template/engine.py", line 143, in get_template
    template, origin = self.find_template(template_name)
  File "/workspace/mbittest/SuperHong/lib/python3.7/site-packages/django/template/engine.py", line 125, in find_template
    template = loader.get_template(name, skip=skip)
  File "/workspace/mbittest/SuperHong/lib/python3.7/site-packages/django/template/loaders/base.py", line 30, in get_template
    contents, origin, origin.template_name, self.engine,
  File "/workspace/mbittest/SuperHong/lib/python3.7/site-packages/django/template/base.py", line 155, in __init__
    self.nodelist = self.compile_nodelist()
  File "/workspace/mbittest/SuperHong/lib/python3.7/site-packages/django/template/base.py", line 193, in compile_nodelist
    return parser.parse()
  File "/workspace/mbittest/SuperHong/lib/python3.7/site-packages/django/template/base.py", line 478, in parse
    raise self.error(token, e)
  File "/workspace/mbittest/SuperHong/lib/python3.7/site-packages/django/template/base.py", line 476, in parse
    compiled_result = compile_func(self, token)
  File "/workspace/mbittest/SuperHong/lib/python3.7/site-packages/django/template/loader_tags.py", line 278, in do_extends
    nodelist = parser.parse()
  File "/workspace/mbittest/SuperHong/lib/python3.7/site-packages/django/template/base.py", line 478, in parse
    raise self.error(token, e)
  File "/workspace/mbittest/SuperHong/lib/python3.7/site-packages/django/template/base.py", line 476, in parse
    compiled_result = compile_func(self, token)
  File "/workspace/mbittest/SuperHong/lib/python3.7/site-packages/django/template/loader_tags.py", line 278, in do_extends
    nodelist = parser.parse()
  File "/workspace/mbittest/SuperHong/lib/python3.7/site-packages/django/template/base.py", line 478, in parse
    raise self.error(token, e)
  File "/workspace/mbittest/SuperHong/lib/python3.7/site-packages/django/template/base.py", line 476, in parse
    compiled_result = compile_func(self, token)
  File "/workspace/mbittest/SuperHong/lib/python3.7/site-packages/django/template/loader_tags.py", line 212, in do_block
    raise TemplateSyntaxError("'%s' tag with name '%s' appears more than once" % (bits[0], block_name))
django.template.exceptions.TemplateSyntaxError: 'block' tag with name 'head' appears more than once
[pid: 18262|app: 0|req: 7/7] 172.17.0.1 () {60 vars in 2859 bytes} [Sun Aug 29 22:18:11 2021] GET /result/5/ => generated 169696 bytes in 580 msecs (HTTP/1.1 500) 6 headers in 187 bytes (1 switches on core 0)
[pid: 18262|app: 0|req: 8/8] 172.17.0.1 () {60 vars in 2859 bytes} [Sun Aug 29 22:19:00 2021] GET /result/5/ => generated 5453 bytes in 89 msecs (HTTP/1.1 200) 5 headers in 167 bytes (2 switches on core 0)
[pid: 18262|app: 0|req: 9/9] 172.17.0.1 () {58 vars in 2792 bytes} [Sun Aug 29 22:19:18 2021] GET / => generated 2019 bytes in 27 msecs (HTTP/1.1 200) 5 headers in 167 bytes (1 switches on core 0)
[pid: 18262|app: 0|req: 10/10] 172.17.0.1 () {58 vars in 2815 bytes} [Sun Aug 29 22:19:19 2021] GET /form/ => generated 34779 bytes in 433 msecs (HTTP/1.1 200) 7 headers in 350 bytes (1 switches on core 0)
Internal Server Error: /submit/
Traceback (most recent call last):
  File "/workspace/mbittest/SuperHong/lib/python3.7/site-packages/django/core/handlers/exception.py", line 47, in inner
    response = get_response(request)
  File "/workspace/mbittest/SuperHong/lib/python3.7/site-packages/django/core/handlers/base.py", line 181, in _get_response
    response = wrapped_callback(request, *callback_args, **callback_kwargs)
  File "./main/views.py", line 34, in submit
    developer_id = int(request.POST[f'question-{n}'][0])
IndexError: string index out of range
[pid: 18262|app: 0|req: 11/11] 172.17.0.1 () {66 vars in 3022 bytes} [Sun Aug 29 22:19:33 2021] POST /submit/ => generated 63318 bytes in 233 msecs (HTTP/1.1 500) 6 headers in 186 bytes (1 switches on core 0)
[pid: 18262|app: 0|req: 12/12] 172.17.0.1 () {58 vars in 2792 bytes} [Sun Aug 29 22:24:32 2021] GET / => generated 2019 bytes in 12 msecs (HTTP/1.1 200) 5 headers in 167 bytes (1 switches on core 0)
[pid: 18262|app: 0|req: 13/13] 172.17.0.1 () {58 vars in 2815 bytes} [Sun Aug 29 22:24:33 2021] GET /form/ => generated 34779 bytes in 392 msecs (HTTP/1.1 200) 7 headers in 350 bytes (1 switches on core 0)
Internal Server Error: /submit/
Traceback (most recent call last):
  File "/workspace/mbittest/SuperHong/lib/python3.7/site-packages/django/core/handlers/exception.py", line 47, in inner
    response = get_response(request)
  File "/workspace/mbittest/SuperHong/lib/python3.7/site-packages/django/core/handlers/base.py", line 181, in _get_response
    response = wrapped_callback(request, *callback_args, **callback_kwargs)
  File "./main/views.py", line 34, in submit
    developer_id = int(request.POST[f'question-{n}'][0])
IndexError: string index out of range
[pid: 18262|app: 0|req: 14/14] 172.17.0.1 () {66 vars in 3022 bytes} [Sun Aug 29 22:24:47 2021] POST /submit/ => generated 63318 bytes in 153 msecs (HTTP/1.1 500) 6 headers in 186 bytes (1 switches on core 0)
[pid: 18262|app: 0|req: 15/15] 172.17.0.1 () {58 vars in 2792 bytes} [Sun Aug 29 22:27:47 2021] GET / => generated 2019 bytes in 34 msecs (HTTP/1.1 200) 5 headers in 167 bytes (1 switches on core 0)
[pid: 18262|app: 0|req: 16/16] 172.17.0.1 () {58 vars in 2815 bytes} [Sun Aug 29 22:27:48 2021] GET /form/ => generated 34779 bytes in 311 msecs (HTTP/1.1 200) 7 headers in 350 bytes (1 switches on core 0)
Internal Server Error: /submit/
Traceback (most recent call last):
  File "/workspace/mbittest/SuperHong/lib/python3.7/site-packages/django/core/handlers/exception.py", line 47, in inner
    response = get_response(request)
  File "/workspace/mbittest/SuperHong/lib/python3.7/site-packages/django/core/handlers/base.py", line 181, in _get_response
    response = wrapped_callback(request, *callback_args, **callback_kwargs)
  File "./main/views.py", line 34, in submit
    developer_id = int(request.POST[f'question-{n}'][0])
IndexError: string index out of range
[pid: 18262|app: 0|req: 17/17] 172.17.0.1 () {66 vars in 3022 bytes} [Sun Aug 29 22:28:03 2021] POST /submit/ => generated 63318 bytes in 213 msecs (HTTP/1.1 500) 6 headers in 186 bytes (1 switches on core 0)
[pid: 18262|app: 0|req: 18/18] 172.17.0.1 () {58 vars in 2838 bytes} [Sun Aug 29 22:30:53 2021] GET / => generated 2019 bytes in 7 msecs (HTTP/1.1 200) 5 headers in 167 bytes (1 switches on core 0)
[pid: 18262|app: 0|req: 19/19] 172.17.0.1 () {58 vars in 2861 bytes} [Sun Aug 29 22:30:54 2021] GET /form/ => generated 34779 bytes in 297 msecs (HTTP/1.1 200) 7 headers in 350 bytes (1 switches on core 0)
SIGINT/SIGQUIT received...killing workers...
worker 1 buried after 1 seconds
goodbye to uWSGI.
VACUUM: pidfile removed.
VACUUM: unix socket /workspace/mbittest/tmp/MBIT.sock removed.
*** Starting uWSGI 2.0.19.1 (64bit) on [Sun Aug 29 22:31:02 2021] ***
compiled with version: 7.5.0 on 29 August 2021 18:36:23
os: Linux-4.4.0-1128-aws #142-Ubuntu SMP Fri Apr 16 12:42:33 UTC 2021
nodename: goorm
machine: x86_64
clock source: unix
pcre jit disabled
detected number of CPU cores: 2
current working directory: /workspace/mbittest
writing pidfile to /workspace/mbittest/tmp/MBIT.pid
detected binary path: /workspace/mbittest/SuperHong/bin/uwsgi
chdir() to /workspace/mbittest/
your memory page size is 4096 bytes
detected max file descriptor number: 1024
building mime-types dictionary from file /etc/mime.types...554 entry found
lock engine: pthread robust mutexes
thunder lock: disabled (you can enable it with --thunder-lock)
uwsgi socket 0 bound to UNIX address /workspace/mbittest/tmp/MBIT.sock fd 3
*** WARNING: you are running uWSGI as root !!! (use the --uid flag) *** 
Python version: 3.7.4 (default, Nov  4 2020, 10:17:35)  [GCC 7.4.0]
PEP 405 virtualenv detected: /workspace/mbittest/SuperHong/
Set PythonHome to /workspace/mbittest/SuperHong/
Python main interpreter initialized at 0x55e3c5e20220
*** WARNING: you are running uWSGI as root !!! (use the --uid flag) *** 
python threads support enabled
your server socket listen backlog is limited to 100 connections
your mercy for graceful operations on workers is 60 seconds
mapped 145840 bytes (142 KB) for 1 cores
*** Operational MODE: single process ***
WSGI app 0 (mountpoint='') ready in 2 seconds on interpreter 0x55e3c5e20220 pid: 18278 (default app)
*** WARNING: you are running uWSGI as root !!! (use the --uid flag) *** 
spawned uWSGI master process (pid: 18278)
spawned uWSGI worker 1 (pid: 18281, cores: 1)
subprocess 18279 exited with code 0
[pid: 18281|app: 0|req: 1/1] 172.17.0.1 () {58 vars in 2838 bytes} [Sun Aug 29 22:31:04 2021] GET / => generated 2019 bytes in 293 msecs (HTTP/1.1 200) 5 headers in 167 bytes (1 switches on core 0)
[pid: 18281|app: 0|req: 2/2] 172.17.0.1 () {58 vars in 2861 bytes} [Sun Aug 29 22:31:05 2021] GET /form/ => generated 34779 bytes in 349 msecs (HTTP/1.1 200) 7 headers in 350 bytes (1 switches on core 0)
Internal Server Error: /submit/
Traceback (most recent call last):
  File "/workspace/mbittest/SuperHong/lib/python3.7/site-packages/django/core/handlers/exception.py", line 47, in inner
    response = get_response(request)
  File "/workspace/mbittest/SuperHong/lib/python3.7/site-packages/django/core/handlers/base.py", line 181, in _get_response
    response = wrapped_callback(request, *callback_args, **callback_kwargs)
  File "./main/views.py", line 34, in submit
    developer_id = int(request.POST[f'question-{n}'][0])
IndexError: string index out of range
[pid: 18281|app: 0|req: 3/3] 172.17.0.1 () {66 vars in 3022 bytes} [Sun Aug 29 22:31:21 2021] POST /submit/ => generated 63318 bytes in 191 msecs (HTTP/1.1 500) 6 headers in 186 bytes (1 switches on core 0)
[pid: 18281|app: 0|req: 4/4] 172.17.0.1 () {56 vars in 2764 bytes} [Sun Aug 29 22:31:38 2021] GET /result/2/ => generated 12438 bytes in 6 msecs (HTTP/1.1 200) 5 headers in 168 bytes (1 switches on core 0)
SIGINT/SIGQUIT received...killing workers...
worker 1 buried after 1 seconds
goodbye to uWSGI.
VACUUM: pidfile removed.
VACUUM: unix socket /workspace/mbittest/tmp/MBIT.sock removed.
*** Starting uWSGI 2.0.19.1 (64bit) on [Sun Aug 29 22:35:37 2021] ***
compiled with version: 7.5.0 on 29 August 2021 18:36:23
os: Linux-4.4.0-1128-aws #142-Ubuntu SMP Fri Apr 16 12:42:33 UTC 2021
nodename: goorm
machine: x86_64
clock source: unix
pcre jit disabled
detected number of CPU cores: 2
current working directory: /workspace/mbittest
writing pidfile to /workspace/mbittest/tmp/MBIT.pid
detected binary path: /workspace/mbittest/SuperHong/bin/uwsgi
chdir() to /workspace/mbittest/
your memory page size is 4096 bytes
detected max file descriptor number: 1024
building mime-types dictionary from file /etc/mime.types...554 entry found
lock engine: pthread robust mutexes
thunder lock: disabled (you can enable it with --thunder-lock)
uwsgi socket 0 bound to UNIX address /workspace/mbittest/tmp/MBIT.sock fd 3
*** WARNING: you are running uWSGI as root !!! (use the --uid flag) *** 
Python version: 3.7.4 (default, Nov  4 2020, 10:17:35)  [GCC 7.4.0]
PEP 405 virtualenv detected: /workspace/mbittest/SuperHong/
Set PythonHome to /workspace/mbittest/SuperHong/
Python main interpreter initialized at 0x55b1f28ab220
*** WARNING: you are running uWSGI as root !!! (use the --uid flag) *** 
python threads support enabled
your server socket listen backlog is limited to 100 connections
your mercy for graceful operations on workers is 60 seconds
mapped 145840 bytes (142 KB) for 1 cores
*** Operational MODE: single process ***
WSGI app 0 (mountpoint='') ready in 2 seconds on interpreter 0x55b1f28ab220 pid: 18297 (default app)
*** WARNING: you are running uWSGI as root !!! (use the --uid flag) *** 
spawned uWSGI master process (pid: 18297)
spawned uWSGI worker 1 (pid: 18300, cores: 1)
subprocess 18298 exited with code 0
[pid: 18300|app: 0|req: 1/1] 172.17.0.1 () {58 vars in 2791 bytes} [Sun Aug 29 22:35:39 2021] GET / => generated 2019 bytes in 212 msecs (HTTP/1.1 200) 5 headers in 167 bytes (1 switches on core 0)
[pid: 18300|app: 0|req: 2/2] 172.17.0.1 () {58 vars in 2814 bytes} [Sun Aug 29 22:35:41 2021] GET /form/ => generated 34779 bytes in 371 msecs (HTTP/1.1 200) 7 headers in 350 bytes (1 switches on core 0)
Internal Server Error: /submit/
Traceback (most recent call last):
  File "/workspace/mbittest/SuperHong/lib/python3.7/site-packages/django/core/handlers/exception.py", line 47, in inner
    response = get_response(request)
  File "/workspace/mbittest/SuperHong/lib/python3.7/site-packages/django/core/handlers/base.py", line 181, in _get_response
    response = wrapped_callback(request, *callback_args, **callback_kwargs)
  File "./main/views.py", line 34, in submit
    developer_id = int(request.POST[f'question-{n}'][0])
IndexError: string index out of range
[pid: 18300|app: 0|req: 3/3] 172.17.0.1 () {66 vars in 3021 bytes} [Sun Aug 29 22:35:59 2021] POST /submit/ => generated 63317 bytes in 331 msecs (HTTP/1.1 500) 6 headers in 186 bytes (1 switches on core 0)
[pid: 18300|app: 0|req: 4/4] 172.17.0.1 () {56 vars in 2763 bytes} [Sun Aug 29 22:36:15 2021] GET /result/2/ => generated 5476 bytes in 6 msecs (HTTP/1.1 200) 5 headers in 167 bytes (1 switches on core 0)
[pid: 18300|app: 0|req: 5/5] 172.17.0.1 () {58 vars in 2794 bytes} [Sun Aug 29 22:37:14 2021] GET /result/2/ => generated 5476 bytes in 6 msecs (HTTP/1.1 200) 5 headers in 167 bytes (1 switches on core 0)
[pid: 18300|app: 0|req: 6/6] 172.17.0.1 () {58 vars in 2794 bytes} [Sun Aug 29 22:37:25 2021] GET /result/2/ => generated 5476 bytes in 82 msecs (HTTP/1.1 200) 5 headers in 167 bytes (1 switches on core 0)
[pid: 18300|app: 0|req: 7/7] 172.17.0.1 () {58 vars in 2794 bytes} [Sun Aug 29 22:37:26 2021] GET /result/2/ => generated 5476 bytes in 17 msecs (HTTP/1.1 200) 5 headers in 167 bytes (1 switches on core 0)
[pid: 18300|app: 0|req: 8/8] 172.17.0.1 () {58 vars in 2794 bytes} [Sun Aug 29 22:37:26 2021] GET /result/2/ => generated 5476 bytes in 9 msecs (HTTP/1.1 200) 5 headers in 167 bytes (1 switches on core 0)
[pid: 18300|app: 0|req: 9/9] 172.17.0.1 () {58 vars in 2794 bytes} [Sun Aug 29 22:37:26 2021] GET /result/2/ => generated 5476 bytes in 14 msecs (HTTP/1.1 200) 5 headers in 167 bytes (1 switches on core 0)
[pid: 18300|app: 0|req: 10/10] 172.17.0.1 () {58 vars in 2794 bytes} [Sun Aug 29 22:37:27 2021] GET /result/2/ => generated 5476 bytes in 28 msecs (HTTP/1.1 200) 5 headers in 167 bytes (1 switches on core 0)
[pid: 18300|app: 0|req: 11/11] 172.17.0.1 () {58 vars in 2794 bytes} [Sun Aug 29 22:37:27 2021] GET /result/2/ => generated 5476 bytes in 7 msecs (HTTP/1.1 200) 5 headers in 167 bytes (1 switches on core 0)
[pid: 18300|app: 0|req: 12/12] 172.17.0.1 () {58 vars in 2794 bytes} [Sun Aug 29 22:37:27 2021] GET /result/2/ => generated 5476 bytes in 6 msecs (HTTP/1.1 200) 5 headers in 167 bytes (1 switches on core 0)
[pid: 18300|app: 0|req: 13/13] 172.17.0.1 () {58 vars in 2791 bytes} [Sun Aug 29 22:48:42 2021] GET / => generated 2019 bytes in 91 msecs (HTTP/1.1 200) 5 headers in 167 bytes (1 switches on core 0)
[pid: 18300|app: 0|req: 14/14] 172.17.0.1 () {58 vars in 2814 bytes} [Sun Aug 29 22:48:43 2021] GET /form/ => generated 34779 bytes in 272 msecs (HTTP/1.1 200) 7 headers in 350 bytes (1 switches on core 0)
[pid: 18300|app: 0|req: 15/15] 172.17.0.1 () {58 vars in 2785 bytes} [Sun Aug 29 22:48:50 2021] GET /result/2 => generated 0 bytes in 1 msecs (HTTP/1.1 301) 5 headers in 178 bytes (1 switches on core 0)
[pid: 18300|app: 0|req: 16/16] 172.17.0.1 () {58 vars in 2787 bytes} [Sun Aug 29 22:48:50 2021] GET /result/2/ => generated 8022 bytes in 11 msecs (HTTP/1.1 200) 5 headers in 167 bytes (1 switches on core 0)
[pid: 18300|app: 0|req: 17/17] 172.17.0.1 () {58 vars in 2787 bytes} [Sun Aug 29 22:56:19 2021] GET /result/2/ => generated 7698 bytes in 49 msecs (HTTP/1.1 200) 5 headers in 167 bytes (1 switches on core 0)
[pid: 18300|app: 0|req: 18/18] 172.17.0.1 () {56 vars in 2745 bytes} [Sun Aug 29 22:56:21 2021] GET / => generated 2019 bytes in 7 msecs (HTTP/1.1 200) 5 headers in 167 bytes (1 switches on core 0)
[pid: 18300|app: 0|req: 19/19] 172.17.0.1 () {58 vars in 2794 bytes} [Sun Aug 29 22:58:31 2021] GET /result/2/ => generated 7698 bytes in 8 msecs (HTTP/1.1 200) 5 headers in 167 bytes (1 switches on core 0)
[pid: 18300|app: 0|req: 20/20] 172.17.0.1 () {58 vars in 2794 bytes} [Sun Aug 29 22:58:31 2021] GET /result/2/ => generated 7698 bytes in 7 msecs (HTTP/1.1 200) 5 headers in 167 bytes (1 switches on core 0)
[pid: 18300|app: 0|req: 21/21] 172.17.0.1 () {58 vars in 2794 bytes} [Sun Aug 29 22:58:31 2021] GET /result/2/ => generated 7698 bytes in 10 msecs (HTTP/1.1 200) 5 headers in 167 bytes (1 switches on core 0)
[pid: 18300|app: 0|req: 22/22] 172.17.0.1 () {58 vars in 2794 bytes} [Sun Aug 29 22:58:31 2021] GET /result/2/ => generated 7698 bytes in 16 msecs (HTTP/1.1 200) 5 headers in 167 bytes (1 switches on core 0)
[pid: 18300|app: 0|req: 23/23] 172.17.0.1 () {58 vars in 2794 bytes} [Sun Aug 29 22:58:31 2021] GET /result/2/ => generated 7698 bytes in 12 msecs (HTTP/1.1 200) 5 headers in 167 bytes (1 switches on core 0)
[pid: 18300|app: 0|req: 24/24] 172.17.0.1 () {58 vars in 2794 bytes} [Sun Aug 29 22:58:32 2021] GET /result/2/ => generated 7698 bytes in 98 msecs (HTTP/1.1 200) 5 headers in 167 bytes (1 switches on core 0)
SIGINT/SIGQUIT received...killing workers...
worker 1 buried after 1 seconds
goodbye to uWSGI.
VACUUM: pidfile removed.
VACUUM: unix socket /workspace/mbittest/tmp/MBIT.sock removed.
*** Starting uWSGI 2.0.19.1 (64bit) on [Sun Aug 29 22:58:39 2021] ***
compiled with version: 7.5.0 on 29 August 2021 18:36:23
os: Linux-4.4.0-1128-aws #142-Ubuntu SMP Fri Apr 16 12:42:33 UTC 2021
nodename: goorm
machine: x86_64
clock source: unix
pcre jit disabled
detected number of CPU cores: 2
current working directory: /workspace/mbittest
writing pidfile to /workspace/mbittest/tmp/MBIT.pid
detected binary path: /workspace/mbittest/SuperHong/bin/uwsgi
chdir() to /workspace/mbittest/
your memory page size is 4096 bytes
detected max file descriptor number: 1024
building mime-types dictionary from file /etc/mime.types...554 entry found
lock engine: pthread robust mutexes
thunder lock: disabled (you can enable it with --thunder-lock)
uwsgi socket 0 bound to UNIX address /workspace/mbittest/tmp/MBIT.sock fd 3
*** WARNING: you are running uWSGI as root !!! (use the --uid flag) *** 
Python version: 3.7.4 (default, Nov  4 2020, 10:17:35)  [GCC 7.4.0]
PEP 405 virtualenv detected: /workspace/mbittest/SuperHong/
Set PythonHome to /workspace/mbittest/SuperHong/
Python main interpreter initialized at 0x55d6901ef220
*** WARNING: you are running uWSGI as root !!! (use the --uid flag) *** 
python threads support enabled
your server socket listen backlog is limited to 100 connections
your mercy for graceful operations on workers is 60 seconds
mapped 145840 bytes (142 KB) for 1 cores
*** Operational MODE: single process ***
WSGI app 0 (mountpoint='') ready in 2 seconds on interpreter 0x55d6901ef220 pid: 18328 (default app)
*** WARNING: you are running uWSGI as root !!! (use the --uid flag) *** 
spawned uWSGI master process (pid: 18328)
spawned uWSGI worker 1 (pid: 18331, cores: 1)
subprocess 18329 exited with code 0
SIGINT/SIGQUIT received...killing workers...
worker 1 buried after 1 seconds
goodbye to uWSGI.
VACUUM: pidfile removed.
VACUUM: unix socket /workspace/mbittest/tmp/MBIT.sock removed.
*** Starting uWSGI 2.0.19.1 (64bit) on [Sun Aug 29 22:58:43 2021] ***
compiled with version: 7.5.0 on 29 August 2021 18:36:23
os: Linux-4.4.0-1128-aws #142-Ubuntu SMP Fri Apr 16 12:42:33 UTC 2021
nodename: goorm
machine: x86_64
clock source: unix
pcre jit disabled
detected number of CPU cores: 2
current working directory: /workspace/mbittest
writing pidfile to /workspace/mbittest/tmp/MBIT.pid
detected binary path: /workspace/mbittest/SuperHong/bin/uwsgi
chdir() to /workspace/mbittest/
your memory page size is 4096 bytes
detected max file descriptor number: 1024
building mime-types dictionary from file /etc/mime.types...554 entry found
lock engine: pthread robust mutexes
thunder lock: disabled (you can enable it with --thunder-lock)
uwsgi socket 0 bound to UNIX address /workspace/mbittest/tmp/MBIT.sock fd 3
*** WARNING: you are running uWSGI as root !!! (use the --uid flag) *** 
Python version: 3.7.4 (default, Nov  4 2020, 10:17:35)  [GCC 7.4.0]
PEP 405 virtualenv detected: /workspace/mbittest/SuperHong/
Set PythonHome to /workspace/mbittest/SuperHong/
Python main interpreter initialized at 0x55b087d02220
*** WARNING: you are running uWSGI as root !!! (use the --uid flag) *** 
python threads support enabled
your server socket listen backlog is limited to 100 connections
your mercy for graceful operations on workers is 60 seconds
mapped 145840 bytes (142 KB) for 1 cores
*** Operational MODE: single process ***
WSGI app 0 (mountpoint='') ready in 1 seconds on interpreter 0x55b087d02220 pid: 18347 (default app)
*** WARNING: you are running uWSGI as root !!! (use the --uid flag) *** 
spawned uWSGI master process (pid: 18347)
spawned uWSGI worker 1 (pid: 18350, cores: 1)
subprocess 18348 exited with code 0
[pid: 18350|app: 0|req: 1/1] 172.17.0.1 () {58 vars in 2791 bytes} [Sun Aug 29 22:58:45 2021] GET / => generated 2019 bytes in 196 msecs (HTTP/1.1 200) 5 headers in 167 bytes (1 switches on core 0)
[pid: 18350|app: 0|req: 2/2] 172.17.0.1 () {56 vars in 2761 bytes} [Sun Aug 29 22:58:51 2021] GET /result/3 => generated 0 bytes in 1 msecs (HTTP/1.1 301) 5 headers in 178 bytes (1 switches on core 0)
[pid: 18350|app: 0|req: 3/3] 172.17.0.1 () {56 vars in 2763 bytes} [Sun Aug 29 22:58:51 2021] GET /result/3/ => generated 7676 bytes in 24 msecs (HTTP/1.1 200) 5 headers in 167 bytes (1 switches on core 0)
[pid: 18350|app: 0|req: 4/4] 172.17.0.1 () {58 vars in 2794 bytes} [Sun Aug 29 22:59:35 2021] GET /result/3/ => generated 7676 bytes in 11 msecs (HTTP/1.1 200) 5 headers in 167 bytes (1 switches on core 0)
